Workbook

Sheet README
A1: 2027年猪周期情景模型（前提：2027年全国生猪均价18元/公斤，为给定前提而非预测）
A2: 快照：股价2026-10-08收盘；资产负债表2026-06-30；经营数据截至2026年8-9月简报。
A3: 切换：Paths!B12 价格路径（1-5），Paths!B13 情景（1熊/2基准/3牛）。其余表全部由公式驱动。
A4: 颜色：黄色=研究假设（可改）；绿色=公司披露事实或管理层目标（来源见Company表basis列与Screening表）。
A5: 利润链条：每公斤毛利=全国价×(1+区域溢价)+渠道溢价−完全成本；养殖利润=育肥头数×出栏重×每公斤毛利；
A6: 归母利润≈(养殖利润+仔猪利润)×归属比例 + 其他业务（未建模=0：温氏黄羽鸡、新希望/大北农/唐人神饲料、华统屠宰等）。
A7: 养殖价差≠归母净利润（少数股东、其他业务、减值、所得税豁免外业务）；情景市盈率≠目标价；归母利润≠股价涨幅。
A8: 成本未披露的公司（华统、新五丰、正邦）不计算情景利润，只给“当前市值=8倍情景利润”所需的成本门槛。
A9: 成本季度路径：从最新披露成本线性滑向2027年假设值，全年均值=假设值（权重见Paths!B31:E31）。
A10: 东瑞售价=全国价×(1+内销溢价d)+出口重量占比s×出口价差e（Paths!B19:D21）。
A11: 历史校准：Hist_PE表为三轮周期市值峰值/峰值年度归母利润，供判断市场在周期高点愿付的倍数。
A12: 数据与脚本：scripts/model_2027.py（Python版，结果与本表一致，见QA表）。

Sheet Paths
A1: 全国生猪均价季度路径（元/公斤）
A3: 路径 | B3: Q1 | C3: Q2 | D3: Q3 | E3: Q4 | F3: 年均
A4: P1 全年持平 | B4: 18 | C4: 18 | D4: 18 | E4: 18 | F4: =AVERAGE(B4:E4)
A5: P2 后高 | B5: 14.5 | C5: 17 | D5: 20 | E5: 20.5 | F5: =AVERAGE(B5:E5)
A6: P3 前高后落 | B6: 19 | C6: 20 | D6: 18 | E6: 15 | F6: =AVERAGE(B6:E6)
A7: P4 期货曲线形状放大 | B7: 15.8953 | C7: 17.4175 | D7: 19.1521 | E7: 19.5351 | F7: =AVERAGE(B7:E7)
A8: P5 V型冲高 | B8: 13 | C8: 18 | D8: 23 | E8: 18 | F8: =AVERAGE(B8:E8)
A9: 参考：期货曲线原值（2026-10-08结算；Q4=Q3×1.02假设） | B9: 11.0425 | C9: 12.1 | D9: 13.305 | E9: 13.5711 | F9: =AVERAGE(B9:E9)
A12: 选定路径（1-5） | B12: 1 | C12: =INDEX(A4:A8,B12)
A13: 选定情景（1熊/2基准/3牛） | B13: 2
A15: 参数 | B15: 熊 | C15: 基准 | D15: 牛 | E15: 选定
A16: 仔猪毛利（元/头） | B16: 80 | C16: 150 | D16: 250 | E16: =INDEX(B16:D16,$B$13)
A19: 东瑞内销溢价d（相对全国均价） | B19: 0.01 | C19: 0.03 | D19: 0.08 | E19: =INDEX(B19:D19,$B$13)
A20: 东瑞出口重量占比s | B20: 0.12 | C20: 0.16 | D20: 0.22 | E20: =INDEX(B20:D20,$B$13)
A21: 东瑞出口−内销价差e（元/公斤） | B21: 1.1 | C21: 2.5 | D21: 4 | E21: =INDEX(B21:D21,$B$13)
A24: “正常年份”全国均价（用于18元超额利润，元/公斤） | B24: 14
A25: 估值倍数1（隐含价格） | B25: 10
A26: 估值倍数2（隐含价格） | B26: 15
A27: 成本门槛倍数 | B27: 8
A28: 选定路径全国价 | B28: Q1 | C28: Q2 | D28: Q3 | E28: Q4 | F28: 年均
B29: =INDEX(B4:B8,$B$12) | C29: =INDEX(C4:C8,$B$12) | D29: =INDEX(D4:D8,$B$12) | E29: =INDEX(E4:E8,$B$12) | F29: =AVERAGE(B29:E29)
A31: 成本滑行权重（成本_q=C2027+w_q×(C最新−C2027)） | B31: 0.375 | C31: 0.125 | D31: -0.125 | E31: -0.375

Sheet Company
A1: 公司输入（黄色=研究假设，绿色=披露数据）
A4: code | B4: 公司 | C4: 市值(亿元,2026-10-08) | D4: 育肥量熊(万头) | E4: 育肥量基准 | F4: 育肥量牛 | G4: 出栏重(kg) | H4: 仔猪(万头) | I4: 最新成本(元/kg) | J4: 2027成本熊 | K4: 2027成本基准 | L4: 2027成本牛 | M4: 区域溢价(相对全国) | N4: 归属比例 | O4: 季节权重Q1 | P4: Q2 | Q4: Q3 | R4: Q4 | S4: 东瑞=1 | T4: 选定育肥量 | U4: 选定成本 | V4: 依据（事实/目标/假设） | W4: 归属比例来源 | X4: 最新成本口径
A5: SZ002714 | B5: 牧原股份 | C5: 2343.14 | D5: 7000 | E5: 7500 | F5: 8000 | G5: 120 | H5: 1000 | I5: 11.5 | J5: 11.8 | K5: 11.3 | L5: 11 | M5: -0.0145 | N5: 0.9621 | O5: 0.236 | P5: 0.256 | Q5: 0.243 | R5: 0.265 | S5: 0 | T5: =INDEX(D5:F5,Paths!$B$13) | U5: =IF(COUNT(J5:L5)=3,INDEX(J5:L5,Paths!$B$13),"") | V5: 量：2026商品猪指引7500-8100、能繁9月计划<300万头（目标/事实）→2027取7500（假设）；重：政策降体重取120kg（假设）；仔猪：2025年1-9月1157万头，2025-08后不再披露，取1000万（假设）；成本：2026-07为11.5（事实），全年目标≤11.5（目标） | W5: 2023-2025盈利年份归母/净利润均值 | X5: 生猪养殖完全成本（调研记录）
A6: SZ300498 | B6: 温氏股份 | C6: 989.44 | D6: 3300 | E6: 3500 | F6: 3700 | G6: 120 | H6: 0 | I6: 12 | J6: 12.2 | K6: 11.7 | L6: 11.4 | M6: -0.0064 | N6: 0.9601 | O6: 0.212 | P6: 0.231 | Q6: 0.241 | R6: 0.316 | S6: 0 | T6: =INDEX(D6:F6,Paths!$B$13) | U6: =IF(COUNT(J6:L6)=3,INDEX(J6:L6,Paths!$B$13),"") | V6: 量：2026年1-9月肉猪年化3535万（事实）；成本：8月<12.0、2026目标11.8（事实/目标）；黄羽鸡等未建模 | W6: 2023-2025盈利年份归母/净利润均值 | X6: 肉猪养殖综合成本<6.0元/斤（上限，换算元/公斤）
A7: SZ000876 | B7: 新希望 | C7: 335.94 | D7: 1350 | E7: 1450 | F7: 1550 | G7: 120 | H7: 140 | I7: 12.5 | J7: 12.8 | K7: 12.3 | L7: 11.9 | M7: -0.0307 | N7: 0.95 | O7: 0.239 | P7: 0.243 | Q7: 0.23 | R7: 0.288 | S7: 0 | T7: =INDEX(D7:F7,Paths!$B$13) | U7: =IF(COUNT(J7:L7)=3,INDEX(J7:L7,Paths!$B$13),"") | V7: 量：2026目标1600万全口径、商品猪年化1431万（目标/事实）；成本：运营场线12.0不含闲置（<1元）→全口径取12.3（假设）；饲料未建模 | W7: 手工（实测值缺失或失真，见筛选输入表） | X7: 运营场线12.0（不含闲置）+闲置影响取0.5（公司称<1元，取中值，假设）
A8: SZ002100 | B8: 天康生物 | C8: 104.03 | D8: 330 | E8: 365 | F8: 390 | G8: 120 | H8: 100 | I8: 11.8 | J8: 12.3 | K8: 11.8 | L8: 11.5 | M8: -0.0757 | N8: 0.84 | O8: 0.254 | P8: 0.225 | Q8: 0.236 | R8: 0.285 | S8: 0 | T8: =INDEX(D8:F8,Paths!$B$13) | U8: =IF(COUNT(J8:L8)=3,INDEX(J8:L8,Paths!$B$13),"") | V8: 量：2026目标475万（天康315+羌都160）含仔猪，按2021年肥猪占比约77%折算（假设）；成本：6月11.8、目标<12（事实/目标）；归属比例按羌都49%少数股东折算 | W8: 手工（实测值缺失或失真，见筛选输入表） | X8: 生猪养殖成本（公司口径，是否含羌都未说明）
A9: SZ001201 | B9: 东瑞股份 | C9: 39.6 | D9: 140 | E9: 160 | F9: 175 | G9: 115 | H9: 40 | I9: 13.8 | J9: 13.5 | K9: 12.9 | L9: 12.5 | M9: 0 | N9: 0.99 | O9: 0.211 | P9: 0.307 | Q9: 0.213 | R9: 0.269 | S9: 1 | T9: =INDEX(D9:F9,Paths!$B$13) | U9: =IF(COUNT(J9:L9)=3,INDEX(J9:L9,Paths!$B$13),"") | V9: 量：2026目标200万（150肉猪+50猪苗等），能繁9.2万持平（事实）；成本：7月13.8，2027目标<12.5（事实/目标），基准取中间偏目标12.9（假设）；售价另按内销/出口拆分 | W9: 手工（实测值缺失或失真，见筛选输入表） | X9: 完全成本（代养13.26）
A10: SZ000048 | B10: 京基智农 | C10: 94.48 | D10: 190 | E10: 210 | F10: 225 | G10: 120 | H10: 0 | I10: 13.3 | J10: 13.3 | K10: 12.6 | L10: 12 | M10: 0.0214 | N10: 0.9809 | O10: 0.212 | P10: 0.247 | Q10: 0.265 | R10: 0.275 | S10: 0 | T10: =INDEX(D10:F10,Paths!$B$13) | U10: =IF(COUNT(J10:L10)=3,INDEX(J10:L10,Paths!$B$13),"") | V10: 量：2026年1-9月商品肥猪年化208万（事实）；成本：3月13.3、目标12.0（事实/目标），基准12.6（假设） | W10: 2023-2025盈利年份归母/净利润均值 | X10: 生猪养殖完全成本（此后未披露）
A11: SH605296 | B11: 神农集团 | C11: 158.58 | D11: 340 | E11: 370 | F11: 400 | G11: 120 | H11: 0 | I11: 12 | J11: 12.1 | K11: 11.7 | L11: 11.4 | M11: -0.0479 | N11: 1 | O11: 0.28 | P11: 0.221 | Q11: 0.185 | R11: 0.314 | S11: 0 | T11: =INDEX(D11:F11,Paths!$B$13) | U11: =IF(COUNT(J11:L11)=3,INDEX(J11:L11,Paths!$B$13),"") | V11: 量：2026目标350万（目标）；成本：7月12.0、目标11.5（事实/目标） | W11: 手工（实测值缺失或失真，见筛选输入表） | X11: 完全成本
A12: SH603477 | B12: 巨星农牧 | C12: 71.91 | D12: 390 | E12: 430 | F12: 470 | G12: 120 | H12: 0 | I12: 12.4 | J12: 12.5 | K12: 12 | L12: 11.6 | M12: -0.025 | N12: 0.9285 | O12: 0.182 | P12: 0.235 | Q12: 0.224 | R12: 0.359 | S12: 0 | T12: =INDEX(D12:F12,Paths!$B$13) | U12: =IF(COUNT(J12:L12)=3,INDEX(J12:L12,Paths!$B$13),"") | V12: 量：2026年1-9月商品肥猪年化427万（事实）；成本：7月<12.4、目标12.0（事实/目标） | W12: 2023-2025盈利年份归母/净利润均值 | X12: 商品肥猪完全成本<6.2元/斤（上限，换算）
A13: SZ002567 | B13: 唐人神 | C13: 51.88 | D13: 320 | E13: 360 | F13: 400 | G13: 120 | H13: 150 | I13: 12.26 | J13: 12.8 | K13: 12.2 | L13: 11.8 | M13: 0 | N13: 0.9 | O13: 0.237 | P13: 0.25 | Q13: 0.219 | R13: 0.294 | S13: 0 | T13: =INDEX(D13:F13,Paths!$B$13) | U13: =IF(COUNT(J13:L13)=3,INDEX(J13:L13,Paths!$B$13),"") | V13: 量：2026目标500万含仔猪约150万（目标/推算）；成本：Q1营业总成本12.66、Q2环比-0.8（事实），基准12.2（假设） | W13: 手工（实测值缺失或失真，见筛选输入表） | X13: Q1营业总成本12.66与Q2（环比-0.8）推算值的均值（推算）
A14: SZ002385 | B14: 大北农 | C14: 132.87 | D14: 360 | E14: 400 | F14: 430 | G14: 120 | H14: 0 | I14: 11.9 | J14: 12.4 | K14: 11.9 | L14: 11.6 | M14: -0.02 | N14: 0.9 | O14: 0.233 | P14: 0.244 | Q14: 0.226 | R14: 0.298 | S14: 0 | T14: =INDEX(D14:F14,Paths!$B$13) | U14: =IF(COUNT(J14:L14)=3,INDEX(J14:L14,Paths!$B$13),"") | V14: 量：2026年1-8月商品肥猪年化396万（事实）；成本：8月略低于12（事实）；饲料未建模 | W14: 手工（实测值缺失或失真，见筛选输入表） | X14: 育肥猪完全成本略低于12元/公斤
A15: SH603363 | B15: 傲农生物 | C15: 75.92 | D15: 120 | E15: 150 | F15: 170 | G15: 120 | H15: 100 | I15: 13 | J15: 13.3 | K15: 12.6 | L15: 12.2 | M15: 0 | N15: 1 | O15: 0.201 | P15: 0.246 | Q15: 0.261 | R15: 0.291 | S15: 0 | T15: =INDEX(D15:F15,Paths!$B$13) | U15: =IF(COUNT(J15:L15)=3,INDEX(J15:L15,Paths!$B$13),"") | V15: 量：2026目标出栏240万，肥猪占比未披露，按60%（假设）；成本：实际未披露，目标12.25（目标），基准12.6（假设，低可信） | W15: 手工（实测值缺失或失真，见筛选输入表） | X15: H1养殖毛利率-18.92%、均价约10.5元反推营业成本约12.5，加期间费用约0.5（推算+假设）
A16: SZ002124 | B16: 天邦食品 | C16: 43.33 | D16: 380 | E16: 450 | F16: 500 | G16: 120 | H16: 250 | I16: 12.65 | J16: 13.2 | K16: 12.5 | L16: 12.2 | M16: -0.036 | N16: 0.9998 | O16: 0.222 | P16: 0.222 | Q16: 0.252 | R16: 0.304 | S16: 0 | T16: =INDEX(D16:F16,Paths!$B$13) | U16: =IF(COUNT(J16:L16)=3,INDEX(J16:L16,Paths!$B$13),"") | V16: 量：2026年1-8月肥猪年化487万（推算）、目标630万含仔猪；成本：H1 12.65、目标12.26（事实/目标）；预重整中，股东权益可能被稀释 | W16: 2023-2025盈利年份归母/净利润均值 | X16: 育肥完全成本（含空栏0.31）
A17: SZ002548 | B17: 金新农 | C17: 31.88 | D17: 70 | E17: 85 | F17: 95 | G17: 120 | H17: 70 | I17: 12.77 | J17: 13.2 | K17: 12.6 | L17: 12.3 | M17: 0.0191 | N17: 0.8781 | O17: 0.225 | P17: 0.203 | Q17: 0.202 | R17: 0.37 | S17: 0 | T17: =INDEX(D17:F17,Paths!$B$13) | U17: =IF(COUNT(J17:L17)=3,INDEX(J17:L17,Paths!$B$13),"") | V17: 量：2026年1-8月商品猪年化80万（推算）、仔猪约70万；成本：4月12.77、目标12.5（事实/目标） | W17: 2023-2025盈利年份归母/净利润均值 | X17: 商品猪销售成本
A18: SZ002840 | B18: 华统股份 | C18: 63.45 | D18: 200 | E18: 230 | F18: 260 | G18: 120 | H18: 0 | M18: -0.0188 | N18: 0.7638 | O18: 0.254 | P18: 0.233 | Q18: 0.231 | R18: 0.283 | S18: 0 | T18: =INDEX(D18:F18,Paths!$B$13) | U18: =IF(COUNT(J18:L18)=3,INDEX(J18:L18,Paths!$B$13),"") | V18: 成本未披露：不计算情景利润，只给成本门槛 | W18: 2023-2025盈利年份归母/净利润均值 | X18: 未披露任何养殖成本
A19: SH600975 | B19: 新五丰 | C19: 63.61 | D19: 290 | E19: 320 | F19: 350 | G19: 120 | H19: 250 | M19: -0.0288 | N19: 0.8256 | O19: 0.25 | P19: 0.25 | Q19: 0.25 | R19: 0.25 | S19: 0 | T19: =INDEX(D19:F19,Paths!$B$13) | U19: =IF(COUNT(J19:L19)=3,INDEX(J19:L19,Paths!$B$13),"") | V19: 成本未披露（只有同比降幅）：不计算情景利润，只给成本门槛 | W19: 2023-2025盈利年份归母/净利润均值 | X19: 未披露绝对值（H1同比-8%）
A20: SZ002157 | B20: 正邦科技 | C20: 266.4 | D20: 420 | E20: 500 | F20: 600 | G20: 120 | H20: 400 | M20: -0.003 | N20: 1 | O20: 0.193 | P20: 0.226 | Q20: 0.253 | R20: 0.329 | S20: 0 | T20: =INDEX(D20:F20,Paths!$B$13) | U20: =IF(COUNT(J20:L20)=3,INDEX(J20:L20,Paths!$B$13),"") | V20: 成本与商品猪拆分未披露：不计算情景利润，只给成本门槛 | W20: 手工（实测值缺失或失真，见筛选输入表） | X20: 未披露

Sheet Quarterly
A1: code | B1: 公司 | C1: 季度 | D1: 全国价 | E1: 公司售价 | F1: 完全成本 | G1: 育肥量(万头) | H1: 每公斤毛利 | I1: 养殖利润(亿元)
A2: SZ002714 | B2: =Company!B5 | C2: 1 | D2: =Paths!B$29 | E2: =IF(Company!$S$5=1,D2*(1+Paths!$E$19)+Paths!$E$20*Paths!$E$21,D2*(1+Company!$M$5)) | F2: =IF(Company!$U$5="","",Company!$U$5+Paths!B$31*(IF(ISNUMBER(Company!$I$5),Company!$I$5,Company!$U$5)-Company!$U$5)) | G2: =Company!$T$5*Company!O$5 | H2: =IF(F2="",0,E2-F2) | I2: =IF(F2="",0,G2*10000*Company!$G$5*H2/100000000)
A3: SZ002714 | B3: =Company!B5 | C3: 2 | D3: =Paths!C$29 | E3: =IF(Company!$S$5=1,D3*(1+Paths!$E$19)+Paths!$E$20*Paths!$E$21,D3*(1+Company!$M$5)) | F3: =IF(Company!$U$5="","",Company!$U$5+Paths!C$31*(IF(ISNUMBER(Company!$I$5),Company!$I$5,Company!$U$5)-Company!$U$5)) | G3: =Company!$T$5*Company!P$5 | H3: =IF(F3="",0,E3-F3) | I3: =IF(F3="",0,G3*10000*Company!$G$5*H3/100000000)
A4: SZ002714 | B4: =Company!B5 | C4: 3 | D4: =Paths!D$29 | E4: =IF(Company!$S$5=1,D4*(1+Paths!$E$19)+Paths!$E$20*Paths!$E$21,D4*(1+Company!$M$5)) | F4: =IF(Company!$U$5="","",Company!$U$5+Paths!D$31*(IF(ISNUMBER(Company!$I$5),Company!$I$5,Company!$U$5)-Company!$U$5)) | G4: =Company!$T$5*Company!Q$5 | H4: =IF(F4="",0,E4-F4) | I4: =IF(F4="",0,G4*10000*Company!$G$5*H4/100000000)
A5: SZ002714 | B5: =Company!B5 | C5: 4 | D5: =Paths!E$29 | E5: =IF(Company!$S$5=1,D5*(1+Paths!$E$19)+Paths!$E$20*Paths!$E$21,D5*(1+Company!$M$5)) | F5: =IF(Company!$U$5="","",Company!$U$5+Paths!E$31*(IF(ISNUMBER(Company!$I$5),Company!$I$5,Company!$U$5)-Company!$U$5)) | G5: =Company!$T$5*Company!R$5 | H5: =IF(F5="",0,E5-F5) | I5: =IF(F5="",0,G5*10000*Company!$G$5*H5/100000000)
A6: SZ300498 | B6: =Company!B6 | C6: 1 | D6: =Paths!B$29 | E6: =IF(Company!$S$6=1,D6*(1+Paths!$E$19)+Paths!$E$20*Paths!$E$21,D6*(1+Company!$M$6)) | F6: =IF(Company!$U$6="","",Company!$U$6+Paths!B$31*(IF(ISNUMBER(Company!$I$6),Company!$I$6,Company!$U$6)-Company!$U$6)) | G6: =Company!$T$6*Company!O$6 | H6: =IF(F6="",0,E6-F6) | I6: =IF(F6="",0,G6*10000*Company!$G$6*H6/100000000)
A7: SZ300498 | B7: =Company!B6 | C7: 2 | D7: =Paths!C$29 | E7: =IF(Company!$S$6=1,D7*(1+Paths!$E$19)+Paths!$E$20*Paths!$E$21,D7*(1+Company!$M$6)) | F7: =IF(Company!$U$6="","",Company!$U$6+Paths!C$31*(IF(ISNUMBER(Company!$I$6),Company!$I$6,Company!$U$6)-Company!$U$6)) | G7: =Company!$T$6*Company!P$6 | H7: =IF(F7="",0,E7-F7) | I7: =IF(F7="",0,G7*10000*Company!$G$6*H7/100000000)
A8: SZ300498 | B8: =Company!B6 | C8: 3 | D8: =Paths!D$29 | E8: =IF(Company!$S$6=1,D8*(1+Paths!$E$19)+Paths!$E$20*Paths!$E$21,D8*(1+Company!$M$6)) | F8: =IF(Company!$U$6="","",Company!$U$6+Paths!D$31*(IF(ISNUMBER(Company!$I$6),Company!$I$6,Company!$U$6)-Company!$U$6)) | G8: =Company!$T$6*Company!Q$6 | H8: =IF(F8="",0,E8-F8) | I8: =IF(F8="",0,G8*10000*Company!$G$6*H8/100000000)
A9: SZ300498 | B9: =Company!B6 | C9: 4 | D9: =Paths!E$29 | E9: =IF(Company!$S$6=1,D9*(1+Paths!$E$19)+Paths!$E$20*Paths!$E$21,D9*(1+Company!$M$6)) | F9: =IF(Company!$U$6="","",Company!$U$6+Paths!E$31*(IF(ISNUMBER(Company!$I$6),Company!$I$6,Company!$U$6)-Company!$U$6)) | G9: =Company!$T$6*Company!R$6 | H9: =IF(F9="",0,E9-F9) | I9: =IF(F9="",0,G9*10000*Company!$G$6*H9/100000000)
A10: SZ000876 | B10: =Company!B7 | C10: 1 | D10: =Paths!B$29 | E10: =IF(Company!$S$7=1,D10*(1+Paths!$E$19)+Paths!$E$20*Paths!$E$21,D10*(1+Company!$M$7)) | F10: =IF(Company!$U$7="","",Company!$U$7+Paths!B$31*(IF(ISNUMBER(Company!$I$7),Company!$I$7,Company!$U$7)-Company!$U$7)) | G10: =Company!$T$7*Company!O$7 | H10: =IF(F10="",0,E10-F10) | I10: =IF(F10="",0,G10*10000*Company!$G$7*H10/100000000)
A11: SZ000876 | B11: =Company!B7 | C11: 2 | D11: =Paths!C$29 | E11: =IF(Company!$S$7=1,D11*(1+Paths!$E$19)+Paths!$E$20*Paths!$E$21,D11*(1+Company!$M$7)) | F11: =IF(Company!$U$7="","",Company!$U$7+Paths!C$31*(IF(ISNUMBER(Company!$I$7),Company!$I$7,Company!$U$7)-Company!$U$7)) | G11: =Company!$T$7*Company!P$7 | H11: =IF(F11="",0,E11-F11) | I11: =IF(F11="",0,G11*10000*Company!$G$7*H11/100000000)
A12: SZ000876 | B12: =Company!B7 | C12: 3 | D12: =Paths!D$29 | E12: =IF(Company!$S$7=1,D12*(1+Paths!$E$19)+Paths!$E$20*Paths!$E$21,D12*(1+Company!$M$7)) | F12: =IF(Company!$U$7="","",Company!$U$7+Paths!D$31*(IF(ISNUMBER(Company!$I$7),Company!$I$7,Company!$U$7)-Company!$U$7)) | G12: =Company!$T$7*Company!Q$7 | H12: =IF(F12="",0,E12-F12) | I12: =IF(F12="",0,G12*10000*Company!$G$7*H12/100000000)
A13: SZ000876 | B13: =Company!B7 | C13: 4 | D13: =Paths!E$29 | E13: =IF(Company!$S$7=1,D13*(1+Paths!$E$19)+Paths!$E$20*Paths!$E$21,D13*(1+Company!$M$7)) | F13: =IF(Company!$U$7="","",Company!$U$7+Paths!E$31*(IF(ISNUMBER(Company!$I$7),Company!$I$7,Company!$U$7)-Company!$U$7)) | G13: =Company!$T$7*Company!R$7 | H13: =IF(F13="",0,E13-F13) | I13: =IF(F13="",0,G13*10000*Company!$G$7*H13/100000000)
A14: SZ002100 | B14: =Company!B8 | C14: 1 | D14: =Paths!B$29 | E14: =IF(Company!$S$8=1,D14*(1+Paths!$E$19)+Paths!$E$20*Paths!$E$21,D14*(1+Company!$M$8)) | F14: =IF(Company!$U$8="","",Company!$U$8+Paths!B$31*(IF(ISNUMBER(Company!$I$8),Company!$I$8,Company!$U$8)-Company!$U$8)) | G14: =Company!$T$8*Company!O$8 | H14: =IF(F14="",0,E14-F14) | I14: =IF(F14="",0,G14*10000*Company!$G$8*H14/100000000)
A15: SZ002100 | B15: =Company!B8 | C15: 2 | D15: =Paths!C$29 | E15: =IF(Company!$S$8=1,D15*(1+Paths!$E$19)+Paths!$E$20*Paths!$E$21,D15*(1+Company!$M$8)) | F15: =IF(Company!$U$8="","",Company!$U$8+Paths!C$31*(IF(ISNUMBER(Company!$I$8),Company!$I$8,Company!$U$8)-Company!$U$8)) | G15: =Company!$T$8*Company!P$8 | H15: =IF(F15="",0,E15-F15) | I15: =IF(F15="",0,G15*10000*Company!$G$8*H15/100000000)
A16: SZ002100 | B16: =Company!B8 | C16: 3 | D16: =Paths!D$29 | E16: =IF(Company!$S$8=1,D16*(1+Paths!$E$19)+Paths!$E$20*Paths!$E$21,D16*(1+Company!$M$8)) | F16: =IF(Company!$U$8="","",Company!$U$8+Paths!D$31*(IF(ISNUMBER(Company!$I$8),Company!$I$8,Company!$U$8)-Company!$U$8)) | G16: =Company!$T$8*Company!Q$8 | H16: =IF(F16="",0,E16-F16) | I16: =IF(F16="",0,G16*10000*Company!$G$8*H16/100000000)
A17: SZ002100 | B17: =Company!B8 | C17: 4 | D17: =Paths!E$29 | E17: =IF(Company!$S$8=1,D17*(1+Paths!$E$19)+Paths!$E$20*Paths!$E$21,D17*(1+Company!$M$8)) | F17: =IF(Company!$U$8="","",Company!$U$8+Paths!E$31*(IF(ISNUMBER(Company!$I$8),Company!$I$8,Company!$U$8)-Company!$U$8)) | G17: =Company!$T$8*Company!R$8 | H17: =IF(F17="",0,E17-F17) | I17: =IF(F17="",0,G17*10000*Company!$G$8*H17/100000000)
A18: SZ001201 | B18: =Company!B9 | C18: 1 | D18: =Paths!B$29 | E18: =IF(Company!$S$9=1,D18*(1+Paths!$E$19)+Paths!$E$20*Paths!$E$21,D18*(1+Company!$M$9)) | F18: =IF(Company!$U$9="","",Company!$U$9+Paths!B$31*(IF(ISNUMBER(Company!$I$9),Company!$I$9,Company!$U$9)-Company!$U$9)) | G18: =Company!$T$9*Company!O$9 | H18: =IF(F18="",0,E18-F18) | I18: =IF(F18="",0,G18*10000*Company!$G$9*H18/100000000)
A19: SZ001201 | B19: =Company!B9 | C19: 2 | D19: =Paths!C$29 | E19: =IF(Company!$S$9=1,D19*(1+Paths!$E$19)+Paths!$E$20*Paths!$E$21,D19*(1+Company!$M$9)) | F19: =IF(Company!$U$9="","",Company!$U$9+Paths!C$31*(IF(ISNUMBER(Company!$I$9),Company!$I$9,Company!$U$9)-Company!$U$9)) | G19: =Company!$T$9*Company!P$9 | H19: =IF(F19="",0,E19-F19) | I19: =IF(F19="",0,G19*10000*Company!$G$9*H19/100000000)
A20: SZ001201 | B20: =Company!B9 | C20: 3 | D20: =Paths!D$29 | E20: =IF(Company!$S$9=1,D20*(1+Paths!$E$19)+Paths!$E$20*Paths!$E$21,D20*(1+Company!$M$9)) | F20: =IF(Company!$U$9="","",Company!$U$9+Paths!D$31*(IF(ISNUMBER(Company!$I$9),Company!$I$9,Company!$U$9)-Company!$U$9)) | G20: =Company!$T$9*Company!Q$9 | H20: =IF(F20="",0,E20-F20) | I20: =IF(F20="",0,G20*10000*Company!$G$9*H20/100000000)
A21: SZ001201 | B21: =Company!B9 | C21: 4 | D21: =Paths!E$29 | E21: =IF(Company!$S$9=1,D21*(1+Paths!$E$19)+Paths!$E$20*Paths!$E$21,D21*(1+Company!$M$9)) | F21: =IF(Company!$U$9="","",Company!$U$9+Paths!E$31*(IF(ISNUMBER(Company!$I$9),Company!$I$9,Company!$U$9)-Company!$U$9)) | G21: =Company!$T$9*Company!R$9 | H21: =IF(F21="",0,E21-F21) | I21: =IF(F21="",0,G21*10000*Company!$G$9*H21/100000000)
A22: SZ000048 | B22: =Company!B10 | C22: 1 | D22: =Paths!B$29 | E22: =IF(Company!$S$10=1,D22*(1+Paths!$E$19)+Paths!$E$20*Paths!$E$21,D22*(1+Company!$M$10)) | F22: =IF(Company!$U$10="","",Company!$U$10+Paths!B$31*(IF(ISNUMBER(Company!$I$10),Company!$I$10,Company!$U$10)-Company!$U$10)) | G22: =Company!$T$10*Company!O$10 | H22: =IF(F22="",0,E22-F22) | I22: =IF(F22="",0,G22*10000*Company!$G$10*H22/100000000)
A23: SZ000048 | B23: =Company!B10 | C23: 2 | D23: =Paths!C$29 | E23: =IF(Company!$S$10=1,D23*(1+Paths!$E$19)+Paths!$E$20*Paths!$E$21,D23*(1+Company!$M$10)) | F23: =IF(Company!$U$10="","",Company!$U$10+Paths!C$31*(IF(ISNUMBER(Company!$I$10),Company!$I$10,Company!$U$10)-Company!$U$10)) | G23: =Company!$T$10*Company!P$10 | H23: =IF(F23="",0,E23-F23) | I23: =IF(F23="",0,G23*10000*Company!$G$10*H23/100000000)
A24: SZ000048 | B24: =Company!B10 | C24: 3 | D24: =Paths!D$29 | E24: =IF(Company!$S$10=1,D24*(1+Paths!$E$19)+Paths!$E$20*Paths!$E$21,D24*(1+Company!$M$10)) | F24: =IF(Company!$U$10="","",Company!$U$10+Paths!D$31*(IF(ISNUMBER(Company!$I$10),Company!$I$10,Company!$U$10)-Company!$U$10)) | G24: =Company!$T$10*Company!Q$10 | H24: =IF(F24="",0,E24-F24) | I24: =IF(F24="",0,G24*10000*Company!$G$10*H24/100000000)
A25: SZ000048 | B25: =Company!B10 | C25: 4 | D25: =Paths!E$29 | E25: =IF(Company!$S$10=1,D25*(1+Paths!$E$19)+Paths!$E$20*Paths!$E$21,D25*(1+Company!$M$10)) | F25: =IF(Company!$U$10="","",Company!$U$10+Paths!E$31*(IF(ISNUMBER(Company!$I$10),Company!$I$10,Company!$U$10)-Company!$U$10)) | G25: =Company!$T$10*Company!R$10 | H25: =IF(F25="",0,E25-F25) | I25: =IF(F25="",0,G25*10000*Company!$G$10*H25/100000000)
A26: SH605296 | B26: =Company!B11 | C26: 1 | D26: =Paths!B$29 | E26: =IF(Company!$S$11=1,D26*(1+Paths!$E$19)+Paths!$E$20*Paths!$E$21,D26*(1+Company!$M$11)) | F26: =IF(Company!$U$11="","",Company!$U$11+Paths!B$31*(IF(ISNUMBER(Company!$I$11),Company!$I$11,Company!$U$11)-Company!$U$11)) | G26: =Company!$T$11*Company!O$11 | H26: =IF(F26="",0,E26-F26) | I26: =IF(F26="",0,G26*10000*Company!$G$11*H26/100000000)
A27: SH605296 | B27: =Company!B11 | C27: 2 | D27: =Paths!C$29 | E27: =IF(Company!$S$11=1,D27*(1+Paths!$E$19)+Paths!$E$20*Paths!$E$21,D27*(1+Company!$M$11)) | F27: =IF(Company!$U$11="","",Company!$U$11+Paths!C$31*(IF(ISNUMBER(Company!$I$11),Company!$I$11,Company!$U$11)-Company!$U$11)) | G27: =Company!$T$11*Company!P$11 | H27: =IF(F27="",0,E27-F27) | I27: =IF(F27="",0,G27*10000*Company!$G$11*H27/100000000)
A28: SH605296 | B28: =Company!B11 | C28: 3 | D28: =Paths!D$29 | E28: =IF(Company!$S$11=1,D28*(1+Paths!$E$19)+Paths!$E$20*Paths!$E$21,D28*(1+Company!$M$11)) | F28: =IF(Company!$U$11="","",Company!$U$11+Paths!D$31*(IF(ISNUMBER(Company!$I$11),Company!$I$11,Company!$U$11)-Company!$U$11)) | G28: =Company!$T$11*Company!Q$11 | H28: =IF(F28="",0,E28-F28) | I28: =IF(F28="",0,G28*10000*Company!$G$11*H28/100000000)
A29: SH605296 | B29: =Company!B11 | C29: 4 | D29: =Paths!E$29 | E29: =IF(Company!$S$11=1,D29*(1+Paths!$E$19)+Paths!$E$20*Paths!$E$21,D29*(1+Company!$M$11)) | F29: =IF(Company!$U$11="","",Company!$U$11+Paths!E$31*(IF(ISNUMBER(Company!$I$11),Company!$I$11,Company!$U$11)-Company!$U$11)) | G29: =Company!$T$11*Company!R$11 | H29: =IF(F29="",0,E29-F29) | I29: =IF(F29="",0,G29*10000*Company!$G$11*H29/100000000)
A30: SH603477 | B30: =Company!B12 | C30: 1 | D30: =Paths!B$29 | E30: =IF(Company!$S$12=1,D30*(1+Paths!$E$19)+Paths!$E$20*Paths!$E$21,D30*(1+Company!$M$12)) | F30: =IF(Company!$U$12="","",Company!$U$12+Paths!B$31*(IF(ISNUMBER(Company!$I$12),Company!$I$12,Company!$U$12)-Company!$U$12)) | G30: =Company!$T$12*Company!O$12 | H30: =IF(F30="",0,E30-F30) | I30: =IF(F30="",0,G30*10000*Company!$G$12*H30/100000000)
A31: SH603477 | B31: =Company!B12 | C31: 2 | D31: =Paths!C$29 | E31: =IF(Company!$S$12=1,D31*(1+Paths!$E$19)+Paths!$E$20*Paths!$E$21,D31*(1+Company!$M$12)) | F31: =IF(Company!$U$12="","",Company!$U$12+Paths!C$31*(IF(ISNUMBER(Company!$I$12),Company!$I$12,Company!$U$12)-Company!$U$12)) | G31: =Company!$T$12*Company!P$12 | H31: =IF(F31="",0,E31-F31) | I31: =IF(F31="",0,G31*10000*Company!$G$12*H31/100000000)
A32: SH603477 | B32: =Company!B12 | C32: 3 | D32: =Paths!D$29 | E32: =IF(Company!$S$12=1,D32*(1+Paths!$E$19)+Paths!$E$20*Paths!$E$21,D32*(1+Company!$M$12)) | F32: =IF(Company!$U$12="","",Company!$U$12+Paths!D$31*(IF(ISNUMBER(Company!$I$12),Company!$I$12,Company!$U$12)-Company!$U$12)) | G32: =Company!$T$12*Company!Q$12 | H32: =IF(F32="",0,E32-F32) | I32: =IF(F32="",0,G32*10000*Company!$G$12*H32/100000000)
A33: SH603477 | B33: =Company!B12 | C33: 4 | D33: =Paths!E$29 | E33: =IF(Company!$S$12=1,D33*(1+Paths!$E$19)+Paths!$E$20*Paths!$E$21,D33*(1+Company!$M$12)) | F33: =IF(Company!$U$12="","",Company!$U$12+Paths!E$31*(IF(ISNUMBER(Company!$I$12),Company!$I$12,Company!$U$12)-Company!$U$12)) | G33: =Company!$T$12*Company!R$12 | H33: =IF(F33="",0,E33-F33) | I33: =IF(F33="",0,G33*10000*Company!$G$12*H33/100000000)
A34: SZ002567 | B34: =Company!B13 | C34: 1 | D34: =Paths!B$29 | E34: =IF(Company!$S$13=1,D34*(1+Paths!$E$19)+Paths!$E$20*Paths!$E$21,D34*(1+Company!$M$13)) | F34: =IF(Company!$U$13="","",Company!$U$13+Paths!B$31*(IF(ISNUMBER(Company!$I$13),Company!$I$13,Company!$U$13)-Company!$U$13)) | G34: =Company!$T$13*Company!O$13 | H34: =IF(F34="",0,E34-F34) | I34: =IF(F34="",0,G34*10000*Company!$G$13*H34/100000000)
A35: SZ002567 | B35: =Company!B13 | C35: 2 | D35: =Paths!C$29 | E35: =IF(Company!$S$13=1,D35*(1+Paths!$E$19)+Paths!$E$20*Paths!$E$21,D35*(1+Company!$M$13)) | F35: =IF(Company!$U$13="","",Company!$U$13+Paths!C$31*(IF(ISNUMBER(Company!$I$13),Company!$I$13,Company!$U$13)-Company!$U$13)) | G35: =Company!$T$13*Company!P$13 | H35: =IF(F35="",0,E35-F35) | I35: =IF(F35="",0,G35*10000*Company!$G$13*H35/100000000)
A36: SZ002567 | B36: =Company!B13 | C36: 3 | D36: =Paths!D$29 | E36: =IF(Company!$S$13=1,D36*(1+Paths!$E$19)+Paths!$E$20*Paths!$E$21,D36*(1+Company!$M$13)) | F36: =IF(Company!$U$13="","",Company!$U$13+Paths!D$31*(IF(ISNUMBER(Company!$I$13),Company!$I$13,Company!$U$13)-Company!$U$13)) | G36: =Company!$T$13*Company!Q$13 | H36: =IF(F36="",0,E36-F36) | I36: =IF(F36="",0,G36*10000*Company!$G$13*H36/100000000)
A37: SZ002567 | B37: =Company!B13 | C37: 4 | D37: =Paths!E$29 | E37: =IF(Company!$S$13=1,D37*(1+Paths!$E$19)+Paths!$E$20*Paths!$E$21,D37*(1+Company!$M$13)) | F37: =IF(Company!$U$13="","",Company!$U$13+Paths!E$31*(IF(ISNUMBER(Company!$I$13),Company!$I$13,Company!$U$13)-Company!$U$13)) | G37: =Company!$T$13*Company!R$13 | H37: =IF(F37="",0,E37-F37) | I37: =IF(F37="",0,G37*10000*Company!$G$13*H37/100000000)
A38: SZ002385 | B38: =Company!B14 | C38: 1 | D38: =Paths!B$29 | E38: =IF(Company!$S$14=1,D38*(1+Paths!$E$19)+Paths!$E$20*Paths!$E$21,D38*(1+Company!$M$14)) | F38: =IF(Company!$U$14="","",Company!$U$14+Paths!B$31*(IF(ISNUMBER(Company!$I$14),Company!$I$14,Company!$U$14)-Company!$U$14)) | G38: =Company!$T$14*Company!O$14 | H38: =IF(F38="",0,E38-F38) | I38: =IF(F38="",0,G38*10000*Company!$G$14*H38/100000000)
A39: SZ002385 | B39: =Company!B14 | C39: 2 | D39: =Paths!C$29 | E39: =IF(Company!$S$14=1,D39*(1+Paths!$E$19)+Paths!$E$20*Paths!$E$21,D39*(1+Company!$M$14)) | F39: =IF(Company!$U$14="","",Company!$U$14+Paths!C$31*(IF(ISNUMBER(Company!$I$14),Company!$I$14,Company!$U$14)-Company!$U$14)) | G39: =Company!$T$14*Company!P$14 | H39: =IF(F39="",0,E39-F39) | I39: =IF(F39="",0,G39*10000*Company!$G$14*H39/100000000)
A40: SZ002385 | B40: =Company!B14 | C40: 3 | D40: =Paths!D$29 | E40: =IF(Company!$S$14=1,D40*(1+Paths!$E$19)+Paths!$E$20*Paths!$E$21,D40*(1+Company!$M$14)) | F40: =IF(Company!$U$14="","",Company!$U$14+Paths!D$31*(IF(ISNUMBER(Company!$I$14),Company!$I$14,Company!$U$14)-Company!$U$14)) | G40: =Company!$T$14*Company!Q$14 | H40: =IF(F40="",0,E40-F40) | I40: =IF(F40="",0,G40*10000*Company!$G$14*H40/100000000)
...

Sheet Summary
A1: ="情景汇总：路径 "&Paths!C12&"，情景 "&CHOOSE(Paths!B13,"熊","基准","牛")
A3: code | B3: 公司 | C3: 市值(亿元) | D3: 量加权售价 | E3: 2027成本(选定) | F3: 每公斤毛利(量加权) | G3: 养殖利润(亿元) | H3: 仔猪利润(亿元) | I3: 归属比例 | J3: 情景归母利润(亿元) | K3: 情景市盈率(倍) | L3: 利润/市值 | M3: 成本门槛(市值=8倍利润) | N3: 每1元/kg对应归母利润(亿元) | O3: 占市值 | P3: 隐含全国价@10倍 | Q3: 隐含全国价@15倍 | R3: 18元相对14元的超额利润(亿元) | S3: 占市值
A4: SZ002714 | B4: =Company!B5 | C4: =Company!C5 | D4: =SUMPRODUCT((Quarterly!$A$2:$A$65=A4)*Quarterly!$E$2:$E$65*Quarterly!$G$2:$G$65)/SUMIF(Quarterly!$A$2:$A$65,A4,Quarterly!$G$2:$G$65) | E4: =Company!U5 | F4: =IF(E4="","",SUMPRODUCT((Quarterly!$A$2:$A$65=A4)*Quarterly!$H$2:$H$65*Quarterly!$G$2:$G$65)/SUMIF(Quarterly!$A$2:$A$65,A4,Quarterly!$G$2:$G$65)) | G4: =IF(E4="","",SUMIF(Quarterly!$A$2:$A$65,A4,Quarterly!$I$2:$I$65)) | H4: =Company!H5*10000*Paths!$E$16/100000000 | I4: =Company!N5 | J4: =IF(G4="","",(G4+H4)*I4) | K4: =IF(J4="","",IF(J4>0,C4/J4,"亏损")) | L4: =IF(J4="","",J4/C4) | M4: =D4-(C4/Paths!$B$27/I4-H4)*100000000/(Company!T5*10000*Company!G5) | N4: =Company!E5*10000*Company!G5/100000000*I4 | O4: =N4/C4 | P4: =IF(Company!K5="","",IF(Company!S5=1,(Company!K5+(C4/Paths!$B$25/I4-Company!H5*10000*Paths!$C$16/100000000)/(Company!E5*10000*Company!G5/100000000)-Paths!$C$20*Paths!$C$21)/(1+Paths!$C$19),(Company!K5+(C4/Paths!$B$25/I4-Company!H5*10000*Paths!$C$16/100000000)/(Company!E5*10000*Company!G5/100000000))/(1+Company!M5))) | Q4: =IF(Company!K5="","",IF(Company!S5=1,(Company!K5+(C4/Paths!$B$26/I4-Company!H5*10000*Paths!$C$16/100000000)/(Company!E5*10000*Company!G5/100000000)-Paths!$C$20*Paths!$C$21)/(1+Paths!$C$19),(Company!K5+(C4/Paths!$B$26/I4-Company!H5*10000*Paths!$C$16/100000000)/(Company!E5*10000*Company!G5/100000000))/(1+Company!M5))) | R4: =N4*(18-Paths!$B$24)*(1+IF(Company!S5=1,Paths!$C$19,Company!M5)) | S4: =R4/C4
A5: SZ300498 | B5: =Company!B6 | C5: =Company!C6 | D5: =SUMPRODUCT((Quarterly!$A$2:$A$65=A5)*Quarterly!$E$2:$E$65*Quarterly!$G$2:$G$65)/SUMIF(Quarterly!$A$2:$A$65,A5,Quarterly!$G$2:$G$65) | E5: =Company!U6 | F5: =IF(E5="","",SUMPRODUCT((Quarterly!$A$2:$A$65=A5)*Quarterly!$H$2:$H$65*Quarterly!$G$2:$G$65)/SUMIF(Quarterly!$A$2:$A$65,A5,Quarterly!$G$2:$G$65)) | G5: =IF(E5="","",SUMIF(Quarterly!$A$2:$A$65,A5,Quarterly!$I$2:$I$65)) | H5: =Company!H6*10000*Paths!$E$16/100000000 | I5: =Company!N6 | J5: =IF(G5="","",(G5+H5)*I5) | K5: =IF(J5="","",IF(J5>0,C5/J5,"亏损")) | L5: =IF(J5="","",J5/C5) | M5: =D5-(C5/Paths!$B$27/I5-H5)*100000000/(Company!T6*10000*Company!G6) | N5: =Company!E6*10000*Company!G6/100000000*I5 | O5: =N5/C5 | P5: =IF(Company!K6="","",IF(Company!S6=1,(Company!K6+(C5/Paths!$B$25/I5-Company!H6*10000*Paths!$C$16/100000000)/(Company!E6*10000*Company!G6/100000000)-Paths!$C$20*Paths!$C$21)/(1+Paths!$C$19),(Company!K6+(C5/Paths!$B$25/I5-Company!H6*10000*Paths!$C$16/100000000)/(Company!E6*10000*Company!G6/100000000))/(1+Company!M6))) | Q5: =IF(Company!K6="","",IF(Company!S6=1,(Company!K6+(C5/Paths!$B$26/I5-Company!H6*10000*Paths!$C$16/100000000)/(Company!E6*10000*Company!G6/100000000)-Paths!$C$20*Paths!$C$21)/(1+Paths!$C$19),(Company!K6+(C5/Paths!$B$26/I5-Company!H6*10000*Paths!$C$16/100000000)/(Company!E6*10000*Company!G6/100000000))/(1+Company!M6))) | R5: =N5*(18-Paths!$B$24)*(1+IF(Company!S6=1,Paths!$C$19,Company!M6)) | S5: =R5/C5
A6: SZ000876 | B6: =Company!B7 | C6: =Company!C7 | D6: =SUMPRODUCT((Quarterly!$A$2:$A$65=A6)*Quarterly!$E$2:$E$65*Quarterly!$G$2:$G$65)/SUMIF(Quarterly!$A$2:$A$65,A6,Quarterly!$G$2:$G$65) | E6: =Company!U7 | F6: =IF(E6="","",SUMPRODUCT((Quarterly!$A$2:$A$65=A6)*Quarterly!$H$2:$H$65*Quarterly!$G$2:$G$65)/SUMIF(Quarterly!$A$2:$A$65,A6,Quarterly!$G$2:$G$65)) | G6: =IF(E6="","",SUMIF(Quarterly!$A$2:$A$65,A6,Quarterly!$I$2:$I$65)) | H6: =Company!H7*10000*Paths!$E$16/100000000 | I6: =Company!N7 | J6: =IF(G6="","",(G6+H6)*I6) | K6: =IF(J6="","",IF(J6>0,C6/J6,"亏损")) | L6: =IF(J6="","",J6/C6) | M6: =D6-(C6/Paths!$B$27/I6-H6)*100000000/(Company!T7*10000*Company!G7) | N6: =Company!E7*10000*Company!G7/100000000*I6 | O6: =N6/C6 | P6: =IF(Company!K7="","",IF(Company!S7=1,(Company!K7+(C6/Paths!$B$25/I6-Company!H7*10000*Paths!$C$16/100000000)/(Company!E7*10000*Company!G7/100000000)-Paths!$C$20*Paths!$C$21)/(1+Paths!$C$19),(Company!K7+(C6/Paths!$B$25/I6-Company!H7*10000*Paths!$C$16/100000000)/(Company!E7*10000*Company!G7/100000000))/(1+Company!M7))) | Q6: =IF(Company!K7="","",IF(Company!S7=1,(Company!K7+(C6/Paths!$B$26/I6-Company!H7*10000*Paths!$C$16/100000000)/(Company!E7*10000*Company!G7/100000000)-Paths!$C$20*Paths!$C$21)/(1+Paths!$C$19),(Company!K7+(C6/Paths!$B$26/I6-Company!H7*10000*Paths!$C$16/100000000)/(Company!E7*10000*Company!G7/100000000))/(1+Company!M7))) | R6: =N6*(18-Paths!$B$24)*(1+IF(Company!S7=1,Paths!$C$19,Company!M7)) | S6: =R6/C6
A7: SZ002100 | B7: =Company!B8 | C7: =Company!C8 | D7: =SUMPRODUCT((Quarterly!$A$2:$A$65=A7)*Quarterly!$E$2:$E$65*Quarterly!$G$2:$G$65)/SUMIF(Quarterly!$A$2:$A$65,A7,Quarterly!$G$2:$G$65) | E7: =Company!U8 | F7: =IF(E7="","",SUMPRODUCT((Quarterly!$A$2:$A$65=A7)*Quarterly!$H$2:$H$65*Quarterly!$G$2:$G$65)/SUMIF(Quarterly!$A$2:$A$65,A7,Quarterly!$G$2:$G$65)) | G7: =IF(E7="","",SUMIF(Quarterly!$A$2:$A$65,A7,Quarterly!$I$2:$I$65)) | H7: =Company!H8*10000*Paths!$E$16/100000000 | I7: =Company!N8 | J7: =IF(G7="","",(G7+H7)*I7) | K7: =IF(J7="","",IF(J7>0,C7/J7,"亏损")) | L7: =IF(J7="","",J7/C7) | M7: =D7-(C7/Paths!$B$27/I7-H7)*100000000/(Company!T8*10000*Company!G8) | N7: =Company!E8*10000*Company!G8/100000000*I7 | O7: =N7/C7 | P7: =IF(Company!K8="","",IF(Company!S8=1,(Company!K8+(C7/Paths!$B$25/I7-Company!H8*10000*Paths!$C$16/100000000)/(Company!E8*10000*Company!G8/100000000)-Paths!$C$20*Paths!$C$21)/(1+Paths!$C$19),(Company!K8+(C7/Paths!$B$25/I7-Company!H8*10000*Paths!$C$16/100000000)/(Company!E8*10000*Company!G8/100000000))/(1+Company!M8))) | Q7: =IF(Company!K8="","",IF(Company!S8=1,(Company!K8+(C7/Paths!$B$26/I7-Company!H8*10000*Paths!$C$16/100000000)/(Company!E8*10000*Company!G8/100000000)-Paths!$C$20*Paths!$C$21)/(1+Paths!$C$19),(Company!K8+(C7/Paths!$B$26/I7-Company!H8*10000*Paths!$C$16/100000000)/(Company!E8*10000*Company!G8/100000000))/(1+Company!M8))) | R7: =N7*(18-Paths!$B$24)*(1+IF(Company!S8=1,Paths!$C$19,Company!M8)) | S7: =R7/C7
A8: SZ001201 | B8: =Company!B9 | C8: =Company!C9 | D8: =SUMPRODUCT((Quarterly!$A$2:$A$65=A8)*Quarterly!$E$2:$E$65*Quarterly!$G$2:$G$65)/SUMIF(Quarterly!$A$2:$A$65,A8,Quarterly!$G$2:$G$65) | E8: =Company!U9 | F8: =IF(E8="","",SUMPRODUCT((Quarterly!$A$2:$A$65=A8)*Quarterly!$H$2:$H$65*Quarterly!$G$2:$G$65)/SUMIF(Quarterly!$A$2:$A$65,A8,Quarterly!$G$2:$G$65)) | G8: =IF(E8="","",SUMIF(Quarterly!$A$2:$A$65,A8,Quarterly!$I$2:$I$65)) | H8: =Company!H9*10000*Paths!$E$16/100000000 | I8: =Company!N9 | J8: =IF(G8="","",(G8+H8)*I8) | K8: =IF(J8="","",IF(J8>0,C8/J8,"亏损")) | L8: =IF(J8="","",J8/C8) | M8: =D8-(C8/Paths!$B$27/I8-H8)*100000000/(Company!T9*10000*Company!G9) | N8: =Company!E9*10000*Company!G9/100000000*I8 | O8: =N8/C8 | P8: =IF(Company!K9="","",IF(Company!S9=1,(Company!K9+(C8/Paths!$B$25/I8-Company!H9*10000*Paths!$C$16/100000000)/(Company!E9*10000*Company!G9/100000000)-Paths!$C$20*Paths!$C$21)/(1+Paths!$C$19),(Company!K9+(C8/Paths!$B$25/I8-Company!H9*10000*Paths!$C$16/100000000)/(Company!E9*10000*Company!G9/100000000))/(1+Company!M9))) | Q8: =IF(Company!K9="","",IF(Company!S9=1,(Company!K9+(C8/Paths!$B$26/I8-Company!H9*10000*Paths!$C$16/100000000)/(Company!E9*10000*Company!G9/100000000)-Paths!$C$20*Paths!$C$21)/(1+Paths!$C$19),(Company!K9+(C8/Paths!$B$26/I8-Company!H9*10000*Paths!$C$16/100000000)/(Company!E9*10000*Company!G9/100000000))/(1+Company!M9))) | R8: =N8*(18-Paths!$B$24)*(1+IF(Company!S9=1,Paths!$C$19,Company!M9)) | S8: =R8/C8
A9: SZ000048 | B9: =Company!B10 | C9: =Company!C10 | D9: =SUMPRODUCT((Quarterly!$A$2:$A$65=A9)*Quarterly!$E$2:$E$65*Quarterly!$G$2:$G$65)/SUMIF(Quarterly!$A$2:$A$65,A9,Quarterly!$G$2:$G$65) | E9: =Company!U10 | F9: =IF(E9="","",SUMPRODUCT((Quarterly!$A$2:$A$65=A9)*Quarterly!$H$2:$H$65*Quarterly!$G$2:$G$65)/SUMIF(Quarterly!$A$2:$A$65,A9,Quarterly!$G$2:$G$65)) | G9: =IF(E9="","",SUMIF(Quarterly!$A$2:$A$65,A9,Quarterly!$I$2:$I$65)) | H9: =Company!H10*10000*Paths!$E$16/100000000 | I9: =Company!N10 | J9: =IF(G9="","",(G9+H9)*I9) | K9: =IF(J9="","",IF(J9>0,C9/J9,"亏损")) | L9: =IF(J9="","",J9/C9) | M9: =D9-(C9/Paths!$B$27/I9-H9)*100000000/(Company!T10*10000*Company!G10) | N9: =Company!E10*10000*Company!G10/100000000*I9 | O9: =N9/C9 | P9: =IF(Company!K10="","",IF(Company!S10=1,(Company!K10+(C9/Paths!$B$25/I9-Company!H10*10000*Paths!$C$16/100000000)/(Company!E10*10000*Company!G10/100000000)-Paths!$C$20*Paths!$C$21)/(1+Paths!$C$19),(Company!K10+(C9/Paths!$B$25/I9-Company!H10*10000*Paths!$C$16/100000000)/(Company!E10*10000*Company!G10/100000000))/(1+Company!M10))) | Q9: =IF(Company!K10="","",IF(Company!S10=1,(Company!K10+(C9/Paths!$B$26/I9-Company!H10*10000*Paths!$C$16/100000000)/(Company!E10*10000*Company!G10/100000000)-Paths!$C$20*Paths!$C$21)/(1+Paths!$C$19),(Company!K10+(C9/Paths!$B$26/I9-Company!H10*10000*Paths!$C$16/100000000)/(Company!E10*10000*Company!G10/100000000))/(1+Company!M10))) | R9: =N9*(18-Paths!$B$24)*(1+IF(Company!S10=1,Paths!$C$19,Company!M10)) | S9: =R9/C9
A10: SH605296 | B10: =Company!B11 | C10: =Company!C11 | D10: =SUMPRODUCT((Quarterly!$A$2:$A$65=A10)*Quarterly!$E$2:$E$65*Quarterly!$G$2:$G$65)/SUMIF(Quarterly!$A$2:$A$65,A10,Quarterly!$G$2:$G$65) | E10: =Company!U11 | F10: =IF(E10="","",SUMPRODUCT((Quarterly!$A$2:$A$65=A10)*Quarterly!$H$2:$H$65*Quarterly!$G$2:$G$65)/SUMIF(Quarterly!$A$2:$A$65,A10,Quarterly!$G$2:$G$65)) | G10: =IF(E10="","",SUMIF(Quarterly!$A$2:$A$65,A10,Quarterly!$I$2:$I$65)) | H10: =Company!H11*10000*Paths!$E$16/100000000 | I10: =Company!N11 | J10: =IF(G10="","",(G10+H10)*I10) | K10: =IF(J10="","",IF(J10>0,C10/J10,"亏损")) | L10: =IF(J10="","",J10/C10) | M10: =D10-(C10/Paths!$B$27/I10-H10)*100000000/(Company!T11*10000*Company!G11) | N10: =Company!E11*10000*Company!G11/100000000*I10 | O10: =N10/C10 | P10: =IF(Company!K11="","",IF(Company!S11=1,(Company!K11+(C10/Paths!$B$25/I10-Company!H11*10000*Paths!$C$16/100000000)/(Company!E11*10000*Company!G11/100000000)-Paths!$C$20*Paths!$C$21)/(1+Paths!$C$19),(Company!K11+(C10/Paths!$B$25/I10-Company!H11*10000*Paths!$C$16/100000000)/(Company!E11*10000*Company!G11/100000000))/(1+Company!M11))) | Q10: =IF(Company!K11="","",IF(Company!S11=1,(Company!K11+(C10/Paths!$B$26/I10-Company!H11*10000*Paths!$C$16/100000000)/(Company!E11*10000*Company!G11/100000000)-Paths!$C$20*Paths!$C$21)/(1+Paths!$C$19),(Company!K11+(C10/Paths!$B$26/I10-Company!H11*10000*Paths!$C$16/100000000)/(Company!E11*10000*Company!G11/100000000))/(1+Company!M11))) | R10: =N10*(18-Paths!$B$24)*(1+IF(Company!S11=1,Paths!$C$19,Company!M11)) | S10: =R10/C10
A11: SH603477 | B11: =Company!B12 | C11: =Company!C12 | D11: =SUMPRODUCT((Quarterly!$A$2:$A$65=A11)*Quarterly!$E$2:$E$65*Quarterly!$G$2:$G$65)/SUMIF(Quarterly!$A$2:$A$65,A11,Quarterly!$G$2:$G$65) | E11: =Company!U12 | F11: =IF(E11="","",SUMPRODUCT((Quarterly!$A$2:$A$65=A11)*Quarterly!$H$2:$H$65*Quarterly!$G$2:$G$65)/SUMIF(Quarterly!$A$2:$A$65,A11,Quarterly!$G$2:$G$65)) | G11: =IF(E11="","",SUMIF(Quarterly!$A$2:$A$65,A11,Quarterly!$I$2:$I$65)) | H11: =Company!H12*10000*Paths!$E$16/100000000 | I11: =Company!N12 | J11: =IF(G11="","",(G11+H11)*I11) | K11: =IF(J11="","",IF(J11>0,C11/J11,"亏损")) | L11: =IF(J11="","",J11/C11) | M11: =D11-(C11/Paths!$B$27/I11-H11)*100000000/(Company!T12*10000*Company!G12) | N11: =Company!E12*10000*Company!G12/100000000*I11 | O11: =N11/C11 | P11: =IF(Company!K12="","",IF(Company!S12=1,(Company!K12+(C11/Paths!$B$25/I11-Company!H12*10000*Paths!$C$16/100000000)/(Company!E12*10000*Company!G12/100000000)-Paths!$C$20*Paths!$C$21)/(1+Paths!$C$19),(Company!K12+(C11/Paths!$B$25/I11-Company!H12*10000*Paths!$C$16/100000000)/(Company!E12*10000*Company!G12/100000000))/(1+Company!M12))) | Q11: =IF(Company!K12="","",IF(Company!S12=1,(Company!K12+(C11/Paths!$B$26/I11-Company!H12*10000*Paths!$C$16/100000000)/(Company!E12*10000*Company!G12/100000000)-Paths!$C$20*Paths!$C$21)/(1+Paths!$C$19),(Company!K12+(C11/Paths!$B$26/I11-Company!H12*10000*Paths!$C$16/100000000)/(Company!E12*10000*Company!G12/100000000))/(1+Company!M12))) | R11: =N11*(18-Paths!$B$24)*(1+IF(Company!S12=1,Paths!$C$19,Company!M12)) | S11: =R11/C11
A12: SZ002567 | B12: =Company!B13 | C12: =Company!C13 | D12: =SUMPRODUCT((Quarterly!$A$2:$A$65=A12)*Quarterly!$E$2:$E$65*Quarterly!$G$2:$G$65)/SUMIF(Quarterly!$A$2:$A$65,A12,Quarterly!$G$2:$G$65) | E12: =Company!U13 | F12: =IF(E12="","",SUMPRODUCT((Quarterly!$A$2:$A$65=A12)*Quarterly!$H$2:$H$65*Quarterly!$G$2:$G$65)/SUMIF(Quarterly!$A$2:$A$65,A12,Quarterly!$G$2:$G$65)) | G12: =IF(E12="","",SUMIF(Quarterly!$A$2:$A$65,A12,Quarterly!$I$2:$I$65)) | H12: =Company!H13*10000*Paths!$E$16/100000000 | I12: =Company!N13 | J12: =IF(G12="","",(G12+H12)*I12) | K12: =IF(J12="","",IF(J12>0,C12/J12,"亏损")) | L12: =IF(J12="","",J12/C12) | M12: =D12-(C12/Paths!$B$27/I12-H12)*100000000/(Company!T13*10000*Company!G13) | N12: =Company!E13*10000*Company!G13/100000000*I12 | O12: =N12/C12 | P12: =IF(Company!K13="","",IF(Company!S13=1,(Company!K13+(C12/Paths!$B$25/I12-Company!H13*10000*Paths!$C$16/100000000)/(Company!E13*10000*Company!G13/100000000)-Paths!$C$20*Paths!$C$21)/(1+Paths!$C$19),(Company!K13+(C12/Paths!$B$25/I12-Company!H13*10000*Paths!$C$16/100000000)/(Company!E13*10000*Company!G13/100000000))/(1+Company!M13))) | Q12: =IF(Company!K13="","",IF(Company!S13=1,(Company!K13+(C12/Paths!$B$26/I12-Company!H13*10000*Paths!$C$16/100000000)/(Company!E13*10000*Company!G13/100000000)-Paths!$C$20*Paths!$C$21)/(1+Paths!$C$19),(Company!K13+(C12/Paths!$B$26/I12-Company!H13*10000*Paths!$C$16/100000000)/(Company!E13*10000*Company!G13/100000000))/(1+Company!M13))) | R12: =N12*(18-Paths!$B$24)*(1+IF(Company!S13=1,Paths!$C$19,Company!M13)) | S12: =R12/C12
A13: SZ002385 | B13: =Company!B14 | C13: =Company!C14 | D13: =SUMPRODUCT((Quarterly!$A$2:$A$65=A13)*Quarterly!$E$2:$E$65*Quarterly!$G$2:$G$65)/SUMIF(Quarterly!$A$2:$A$65,A13,Quarterly!$G$2:$G$65) | E13: =Company!U14 | F13: =IF(E13="","",SUMPRODUCT((Quarterly!$A$2:$A$65=A13)*Quarterly!$H$2:$H$65*Quarterly!$G$2:$G$65)/SUMIF(Quarterly!$A$2:$A$65,A13,Quarterly!$G$2:$G$65)) | G13: =IF(E13="","",SUMIF(Quarterly!$A$2:$A$65,A13,Quarterly!$I$2:$I$65)) | H13: =Company!H14*10000*Paths!$E$16/100000000 | I13: =Company!N14 | J13: =IF(G13="","",(G13+H13)*I13) | K13: =IF(J13="","",IF(J13>0,C13/J13,"亏损")) | L13: =IF(J13="","",J13/C13) | M13: =D13-(C13/Paths!$B$27/I13-H13)*100000000/(Company!T14*10000*Company!G14) | N13: =Company!E14*10000*Company!G14/100000000*I13 | O13: =N13/C13 | P13: =IF(Company!K14="","",IF(Company!S14=1,(Company!K14+(C13/Paths!$B$25/I13-Company!H14*10000*Paths!$C$16/100000000)/(Company!E14*10000*Company!G14/100000000)-Paths!$C$20*Paths!$C$21)/(1+Paths!$C$19),(Company!K14+(C13/Paths!$B$25/I13-Company!H14*10000*Paths!$C$16/100000000)/(Company!E14*10000*Company!G14/100000000))/(1+Company!M14))) | Q13: =IF(Company!K14="","",IF(Company!S14=1,(Company!K14+(C13/Paths!$B$26/I13-Company!H14*10000*Paths!$C$16/100000000)/(Company!E14*10000*Company!G14/100000000)-Paths!$C$20*Paths!$C$21)/(1+Paths!$C$19),(Company!K14+(C13/Paths!$B$26/I13-Company!H14*10000*Paths!$C$16/100000000)/(Company!E14*10000*Company!G14/100000000))/(1+Company!M14))) | R13: =N13*(18-Paths!$B$24)*(1+IF(Company!S14=1,Paths!$C$19,Company!M14)) | S13: =R13/C13
A14: SH603363 | B14: =Company!B15 | C14: =Company!C15 | D14: =SUMPRODUCT((Quarterly!$A$2:$A$65=A14)*Quarterly!$E$2:$E$65*Quarterly!$G$2:$G$65)/SUMIF(Quarterly!$A$2:$A$65,A14,Quarterly!$G$2:$G$65) | E14: =Company!U15 | F14: =IF(E14="","",SUMPRODUCT((Quarterly!$A$2:$A$65=A14)*Quarterly!$H$2:$H$65*Quarterly!$G$2:$G$65)/SUMIF(Quarterly!$A$2:$A$65,A14,Quarterly!$G$2:$G$65)) | G14: =IF(E14="","",SUMIF(Quarterly!$A$2:$A$65,A14,Quarterly!$I$2:$I$65)) | H14: =Company!H15*10000*Paths!$E$16/100000000 | I14: =Company!N15 | J14: =IF(G14="","",(G14+H14)*I14) | K14: =IF(J14="","",IF(J14>0,C14/J14,"亏损")) | L14: =IF(J14="","",J14/C14) | M14: =D14-(C14/Paths!$B$27/I14-H14)*100000000/(Company!T15*10000*Company!G15) | N14: =Company!E15*10000*Company!G15/100000000*I14 | O14: =N14/C14 | P14: =IF(Company!K15="","",IF(Company!S15=1,(Company!K15+(C14/Paths!$B$25/I14-Company!H15*10000*Paths!$C$16/100000000)/(Company!E15*10000*Company!G15/100000000)-Paths!$C$20*Paths!$C$21)/(1+Paths!$C$19),(Company!K15+(C14/Paths!$B$25/I14-Company!H15*10000*Paths!$C$16/100000000)/(Company!E15*10000*Company!G15/100000000))/(1+Company!M15))) | Q14: =IF(Company!K15="","",IF(Company!S15=1,(Company!K15+(C14/Paths!$B$26/I14-Company!H15*10000*Paths!$C$16/100000000)/(Company!E15*10000*Company!G15/100000000)-Paths!$C$20*Paths!$C$21)/(1+Paths!$C$19),(Company!K15+(C14/Paths!$B$26/I14-Company!H15*10000*Paths!$C$16/100000000)/(Company!E15*10000*Company!G15/100000000))/(1+Company!M15))) | R14: =N14*(18-Paths!$B$24)*(1+IF(Company!S15=1,Paths!$C$19,Company!M15)) | S14: =R14/C14
A15: SZ002124 | B15: =Company!B16 | C15: =Company!C16 | D15: =SUMPRODUCT((Quarterly!$A$2:$A$65=A15)*Quarterly!$E$2:$E$65*Quarterly!$G$2:$G$65)/SUMIF(Quarterly!$A$2:$A$65,A15,Quarterly!$G$2:$G$65) | E15: =Company!U16 | F15: =IF(E15="","",SUMPRODUCT((Quarterly!$A$2:$A$65=A15)*Quarterly!$H$2:$H$65*Quarterly!$G$2:$G$65)/SUMIF(Quarterly!$A$2:$A$65,A15,Quarterly!$G$2:$G$65)) | G15: =IF(E15="","",SUMIF(Quarterly!$A$2:$A$65,A15,Quarterly!$I$2:$I$65)) | H15: =Company!H16*10000*Paths!$E$16/100000000 | I15: =Company!N16 | J15: =IF(G15="","",(G15+H15)*I15) | K15: =IF(J15="","",IF(J15>0,C15/J15,"亏损")) | L15: =IF(J15="","",J15/C15) | M15: =D15-(C15/Paths!$B$27/I15-H15)*100000000/(Company!T16*10000*Company!G16) | N15: =Company!E16*10000*Company!G16/100000000*I15 | O15: =N15/C15 | P15: =IF(Company!K16="","",IF(Company!S16=1,(Company!K16+(C15/Paths!$B$25/I15-Company!H16*10000*Paths!$C$16/100000000)/(Company!E16*10000*Company!G16/100000000)-Paths!$C$20*Paths!$C$21)/(1+Paths!$C$19),(Company!K16+(C15/Paths!$B$25/I15-Company!H16*10000*Paths!$C$16/100000000)/(Company!E16*10000*Company!G16/100000000))/(1+Company!M16))) | Q15: =IF(Company!K16="","",IF(Company!S16=1,(Company!K16+(C15/Paths!$B$26/I15-Company!H16*10000*Paths!$C$16/100000000)/(Company!E16*10000*Company!G16/100000000)-Paths!$C$20*Paths!$C$21)/(1+Paths!$C$19),(Company!K16+(C15/Paths!$B$26/I15-Company!H16*10000*Paths!$C$16/100000000)/(Company!E16*10000*Company!G16/100000000))/(1+Company!M16))) | R15: =N15*(18-Paths!$B$24)*(1+IF(Company!S16=1,Paths!$C$19,Company!M16)) | S15: =R15/C15
... A19: SZ002157 | B19: =Company!B20 | C19: =Company!C20 | D19: =SUMPRODUCT((Quarterly!$A$2:$A$65=A19)*Quarterly!$E$2:$E$65*Quarterly!$G$2:$G$65)/SUMIF(Quarterly!$A$2:$A$65,A19,Quarterly!$G$2:$G$65) | E19: =Company!U20 | F19: =IF(E19="","",SUMPRODUCT((Quarterly!$A$2:$A$65=A19)*Quarterly!$H$2:$H$65*Quarterly!$G$2:$G$65)/SUMIF(Quarterly!$A$2:$A$65,A19,Quarterly!$G$2:$G$65)) | G19: =IF(E19="","",SUMIF(Quarterly!$A$2:$A$65,A19,Quarterly!$I$2:$I$65)) | H19: =Company!H20*10000*Paths!$E$16/100000000 | I19: =Company!N20 | J19: =IF(G19="","",(G19+H19)*I19) | K19: =IF(J19="","",IF(J19>0,C19/J19,"亏损")) | L19: =IF(J19="","",J19/C19) | M19: =D19-(C19/Paths!$B$27/I19-H19)*100000000/(Company!T20*10000*Company!G20) | N19: =Company!E20*10000*Company!G20/100000000*I19 | O19: =N19/C19 | P19: =IF(Company!K20="","",IF(Company!S20=1,(Company!K20+(C19/Paths!$B$25/I19-Company!H20*10000*Paths!$C$16/100000000)/(Company!E20*10000*Company!G20/100000000)-Paths!$C$20*Paths!$C$21)/(1+Paths!$C$19),(Company!K20+(C19/Paths!$B$25/I19-Company!H20*10000*Paths!$C$16/100000000)/(Company!E20*10000*Company!G20/100000000))/(1+Company!M20))) | Q19: =IF(Company!K20="","",IF(Company!S20=1,(Company!K20+(C19/Paths!$B$26/I19-Company!H20*10000*Paths!$C$16/100000000)/(Company!E20*10000*Company!G20/100000000)-Paths!$C$20*Paths!$C$21)/(1+Paths!$C$19),(Company!K20+(C19/Paths!$B$26/I19-Company!H20*10000*Paths!$C$16/100000000)/(Company!E20*10000*Company!G20/100000000))/(1+Company!M20))) | R19: =N19*(18-Paths!$B$24)*(1+IF(Company!S20=1,Paths!$C$19,Company!M20)) | S19: =R19/C19

Sheet Dongrui
A1: 东瑞股份：售价拆分与“价格优势是否大于成本差距”检验
A3: 一、出口重量占比估算（配额≠销量）
A4: 2026年供港配额（头，截至9-29） | B4: 214484 | C4: 事实
A5: 供澳配额（头） | B5: 879 | C5: 事实
A6: 配额外供货出口（头，参照2024年出口26.23万−配额完成22.07万） | B6: 41600 | C6: 推断
A7: 2027年育肥出栏（万头） | B7: =Company!E9 | C7: 假设
A8: 出口猪均重/内销猪均重之比 | B8: 0.95 | C8: 假设
A9: 出口重量占比s（若配额与2026持平） | B9: =(B4+B5+B6)*B8/(B7*10000) | C9: 推算
A11: 二、2027年售价矩阵（全国价×内销溢价+出口占比×出口价差），元/公斤
A12: 全国均价 | B12: 熊(d1%,s12%,e1.1) | C12: 基准(d3%,s16%,e2.5) | D12: 牛(d8%,s22%,e4.0) | E12: 牧原同期售价(区域溢价-0.015)
A13: 12 | B13: =A13*(1+Paths!B$19)+Paths!B$20*Paths!B$21 | C13: =A13*(1+Paths!C$19)+Paths!C$20*Paths!C$21 | D13: =A13*(1+Paths!D$19)+Paths!D$20*Paths!D$21 | E13: =A13*(1+Company!M5)
A14: 14 | B14: =A14*(1+Paths!B$19)+Paths!B$20*Paths!B$21 | C14: =A14*(1+Paths!C$19)+Paths!C$20*Paths!C$21 | D14: =A14*(1+Paths!D$19)+Paths!D$20*Paths!D$21 | E14: =A14*(1+Company!M5)
A15: 16 | B15: =A15*(1+Paths!B$19)+Paths!B$20*Paths!B$21 | C15: =A15*(1+Paths!C$19)+Paths!C$20*Paths!C$21 | D15: =A15*(1+Paths!D$19)+Paths!D$20*Paths!D$21 | E15: =A15*(1+Company!M5)
A16: 18 | B16: =A16*(1+Paths!B$19)+Paths!B$20*Paths!B$21 | C16: =A16*(1+Paths!C$19)+Paths!C$20*Paths!C$21 | D16: =A16*(1+Paths!D$19)+Paths!D$20*Paths!D$21 | E16: =A16*(1+Company!M5)
A17: 20 | B17: =A17*(1+Paths!B$19)+Paths!B$20*Paths!B$21 | C17: =A17*(1+Paths!C$19)+Paths!C$20*Paths!C$21 | D17: =A17*(1+Paths!D$19)+Paths!D$20*Paths!D$21 | E17: =A17*(1+Company!M5)
A18: 22 | B18: =A18*(1+Paths!B$19)+Paths!B$20*Paths!B$21 | C18: =A18*(1+Paths!C$19)+Paths!C$20*Paths!C$21 | D18: =A18*(1+Paths!D$19)+Paths!D$20*Paths!D$21 | E18: =A18*(1+Company!M5)
A20: 三、18元下：东瑞相对牧原的价格优势 vs 成本差距（元/公斤）
A21: 情景 | B21: 东瑞售价 | C21: 牧原售价 | D21: 价格优势 | E21: 东瑞成本 | F21: 牧原成本 | G21: 成本差距 | H21: 优势−差距（>0才说明价格优势覆盖成本劣势）
A22: 熊 | B22: =18*(1+Paths!B$19)+Paths!B$20*Paths!B$21 | C22: =18*(1+Company!M5) | D22: =B22-C22 | E22: =Company!J9 | F22: =Company!J5 | G22: =E22-F22 | H22: =D22-G22
A23: 基准 | B23: =18*(1+Paths!C$19)+Paths!C$20*Paths!C$21 | C23: =18*(1+Company!M5) | D23: =B23-C23 | E23: =Company!K9 | F23: =Company!K5 | G23: =E23-F23 | H23: =D23-G23
A24: 牛 | B24: =18*(1+Paths!D$19)+Paths!D$20*Paths!D$21 | C24: =18*(1+Company!M5) | D24: =B24-C24 | E24: =Company!L9 | F24: =Company!L5 | G24: =E24-F24 | H24: =D24-G24
A26: 四、历史：东瑞与牧原的售价差与成本差（事实/推算，元/公斤）
A27: 年份 | B27: 东瑞商品猪均价 | C27: 牧原商品猪均价 | D27: 价格优势 | E27: 东瑞完全成本 | F27: 牧原完全成本（约） | G27: 成本差距 | H27: 优势−差距 | I27: 出口重量占比 | J27: 来源/说明
A28: 2022 | B28: 23.68 | C28: 18.16 | D28: =B28-C28 | E28: 18.1 | F28: 15.7 | G28: =E28-F28 | H28: =D28-G28 | I28: 0.6 | J28: 东瑞售价=招股/问询回复表；成本2021末18.6、2022Q1 17.8、Q3 18.4取约18.1。牧原成本：2023-05-17业绩说明会“2022全年平均商品猪完全成本15.7元/kg左右”
A29: 2023 | B29: 17.13 | C29: 14.42 | D29: =B29-C29 | E29: 17.8 | F29: 15 | G29: =E29-F29 | H29: =D29-G29 | I29: 0.5 | J29: 东瑞2023完全成本17.8（正常场口径，2024-03-01纪要）；牧原2024-05-17业绩说明会“2023年…15.0元/kg左右”
A30: 2024 | B30: 18.16 | C30: 16.45 | D30: =B30-C30 | E30: 16.67 | F30: 14 | G30: =E30-F30 | H30: =D30-G30 | I30: 0.48 | J30: 东瑞16.67（2025-01-20纪要）；牧原2025-03-20“全年平均成本在14元/kg左右”
A31: 2025 | B31: 14.66 | C31: 13.48 | D31: =B31-C31 | E31: 14.6 | F31: 12 | G31: =E31-F31 | H31: =D31-G31 | I31: 0.286 | J31: 东瑞H1 15.0、9月14.4、12月13.93，全年取约14.6（推算）；牧原2026-03-28“全年平均成本降至12元/kg左右”
A32: 2026H1 | B32: 11.41 | C32: 10.48 | D32: =B32-C32 | E32: 13.95 | F32: 11.7 | G32: =E32-F32 | H32: =D32-G32 | I32: 0.19 | J32: 东瑞H1售价11.41（2026-08-28纪要）、成本13.95（2026-07-14纪要）；牧原1-2月约12、3月11.6、7月11.5，H1取约11.7（推算）

Sheet Decomposition
A1: 2026年当前状态→2027年18元基准：利润变化的中点拆分（Δ(V·m)=ΔV·m̄+V̄·Δm）
A2: 2026状态：最近年化育肥量、2026年7-9月新牧网全国均价、最新披露成本；2027：全国18元、基准育肥量与成本。融资影响见利息/公斤列（集团口径，饲料型公司偏高）。
A4: code | B4: 公司 | C4: V2026 | D4: V2027 | E4: 全国价2026 | F4: 全国价2027 | G4: 区域溢价r或东瑞d | H4: 渠道溢价s×e | I4: 成本2026 | J4: 成本2027 | K4: 出栏重 | L4: 毛利2026(元/kg) | M4: 毛利2027 | N4: 养殖利润2026(亿) | O4: 养殖利润2027(亿) | P4: 量贡献 | Q4: 全国价贡献 | R4: 区域溢价贡献 | S4: 渠道溢价贡献 | T4: 成本贡献 | U4: 合计校验 | V4: 利息/公斤(2026H1年化)
A5: SZ002714 | B5: 牧原股份 | C5: 7846.05 | D5: 7500 | E5: 10.8472 | F5: 18 | G5: -0.0145 | H5: 0 | I5: 11.5 | J5: 11.3 | K5: 120 | L5: =E5*(1+G5)+H5-I5 | M5: =F5*(1+G5)+H5-J5 | N5: =C5*L5*10000*K5/100000000 | O5: =D5*M5*10000*K5/100000000 | P5: =(D5-C5)*(L5+M5)/2*10000*K5/100000000 | Q5: =(C5+D5)/2*(F5-E5)*10000*K5/100000000 | R5: =(C5+D5)/2*(F5-E5)*G5*10000*K5/100000000 | S5: 0 | T5: =(C5+D5)/2*(I5-J5)*10000*K5/100000000 | U5: =SUM(P5:T5)-(O5-N5) | V5: 0.219
A6: SZ300498 | B6: 温氏股份 | C6: 3534.89 | D6: 3500 | E6: 10.8472 | F6: 18 | G6: -0.0064 | H6: 0 | I6: 12 | J6: 11.7 | K6: 120 | L6: =E6*(1+G6)+H6-I6 | M6: =F6*(1+G6)+H6-J6 | N6: =C6*L6*10000*K6/100000000 | O6: =D6*M6*10000*K6/100000000 | P6: =(D6-C6)*(L6+M6)/2*10000*K6/100000000 | Q6: =(C6+D6)/2*(F6-E6)*10000*K6/100000000 | R6: =(C6+D6)/2*(F6-E6)*G6*10000*K6/100000000 | S6: 0 | T6: =(C6+D6)/2*(I6-J6)*10000*K6/100000000 | U6: =SUM(P6:T6)-(O6-N6) | V6: 0.187
A7: SZ000876 | B7: 新希望 | C7: 1430.71 | D7: 1450 | E7: 10.8472 | F7: 18 | G7: -0.0307 | H7: 0 | I7: 12.5 | J7: 12.3 | K7: 120 | L7: =E7*(1+G7)+H7-I7 | M7: =F7*(1+G7)+H7-J7 | N7: =C7*L7*10000*K7/100000000 | O7: =D7*M7*10000*K7/100000000 | P7: =(D7-C7)*(L7+M7)/2*10000*K7/100000000 | Q7: =(C7+D7)/2*(F7-E7)*10000*K7/100000000 | R7: =(C7+D7)/2*(F7-E7)*G7*10000*K7/100000000 | S7: 0 | T7: =(C7+D7)/2*(I7-J7)*10000*K7/100000000 | U7: =SUM(P7:T7)-(O7-N7) | V7: 1.118
A8: SZ002100 | B8: 天康生物 | C8: 313.52 | D8: 365 | E8: 10.8472 | F8: 18 | G8: -0.0757 | H8: 0 | I8: 11.8 | J8: 11.8 | K8: 120 | L8: =E8*(1+G8)+H8-I8 | M8: =F8*(1+G8)+H8-J8 | N8: =C8*L8*10000*K8/100000000 | O8: =D8*M8*10000*K8/100000000 | P8: =(D8-C8)*(L8+M8)/2*10000*K8/100000000 | Q8: =(C8+D8)/2*(F8-E8)*10000*K8/100000000 | R8: =(C8+D8)/2*(F8-E8)*G8*10000*K8/100000000 | S8: 0 | T8: =(C8+D8)/2*(I8-J8)*10000*K8/100000000 | U8: =SUM(P8:T8)-(O8-N8) | V8: 0.269
A9: SZ001201 | B9: 东瑞股份 | C9: 130 | D9: 160 | E9: 10.8472 | F9: 18 | G9: 0.03 | H9: 0.4 | I9: 13.8 | J9: 12.9 | K9: 115 | L9: =E9*(1+G9)+H9-I9 | M9: =F9*(1+G9)+H9-J9 | N9: =C9*L9*10000*K9/100000000 | O9: =D9*M9*10000*K9/100000000 | P9: =(D9-C9)*(L9+M9)/2*10000*K9/100000000 | Q9: =(C9+D9)/2*(F9-E9)*10000*K9/100000000 | R9: =(C9+D9)/2*(F9-E9)*G9*10000*K9/100000000 | S9: 0 | T9: =(C9+D9)/2*(I9-J9)*10000*K9/100000000 | U9: =SUM(P9:T9)-(O9-N9) | V9: 0.42
A10: SZ000048 | B10: 京基智农 | C10: 207.73 | D10: 210 | E10: 10.8472 | F10: 18 | G10: 0.0214 | H10: 0 | I10: 13.3 | J10: 12.6 | K10: 120 | L10: =E10*(1+G10)+H10-I10 | M10: =F10*(1+G10)+H10-J10 | N10: =C10*L10*10000*K10/100000000 | O10: =D10*M10*10000*K10/100000000 | P10: =(D10-C10)*(L10+M10)/2*10000*K10/100000000 | Q10: =(C10+D10)/2*(F10-E10)*10000*K10/100000000 | R10: =(C10+D10)/2*(F10-E10)*G10*10000*K10/100000000 | S10: 0 | T10: =(C10+D10)/2*(I10-J10)*10000*K10/100000000 | U10: =SUM(P10:T10)-(O10-N10) | V10: 0.24
A11: SH605296 | B11: 神农集团 | C11: 354.19 | D11: 370 | E11: 10.8472 | F11: 18 | G11: -0.0479 | H11: 0 | I11: 12 | J11: 11.7 | K11: 120 | L11: =E11*(1+G11)+H11-I11 | M11: =F11*(1+G11)+H11-J11 | N11: =C11*L11*10000*K11/100000000 | O11: =D11*M11*10000*K11/100000000 | P11: =(D11-C11)*(L11+M11)/2*10000*K11/100000000 | Q11: =(C11+D11)/2*(F11-E11)*10000*K11/100000000 | R11: =(C11+D11)/2*(F11-E11)*G11*10000*K11/100000000 | S11: 0 | T11: =(C11+D11)/2*(I11-J11)*10000*K11/100000000 | U11: =SUM(P11:T11)-(O11-N11) | V11: 0.073
A12: SH603477 | B12: 巨星农牧 | C12: 426.92 | D12: 430 | E12: 10.8472 | F12: 18 | G12: -0.025 | H12: 0 | I12: 12.4 | J12: 12 | K12: 120 | L12: =E12*(1+G12)+H12-I12 | M12: =F12*(1+G12)+H12-J12 | N12: =C12*L12*10000*K12/100000000 | O12: =D12*M12*10000*K12/100000000 | P12: =(D12-C12)*(L12+M12)/2*10000*K12/100000000 | Q12: =(C12+D12)/2*(F12-E12)*10000*K12/100000000 | R12: =(C12+D12)/2*(F12-E12)*G12*10000*K12/100000000 | S12: 0 | T12: =(C12+D12)/2*(I12-J12)*10000*K12/100000000 | U12: =SUM(P12:T12)-(O12-N12) | V12: 0.379
A13: SZ002567 | B13: 唐人神 | C13: 380.33 | D13: 360 | E13: 10.8472 | F13: 18 | G13: 0 | H13: 0 | I13: 12.26 | J13: 12.2 | K13: 120 | L13: =E13*(1+G13)+H13-I13 | M13: =F13*(1+G13)+H13-J13 | N13: =C13*L13*10000*K13/100000000 | O13: =D13*M13*10000*K13/100000000 | P13: =(D13-C13)*(L13+M13)/2*10000*K13/100000000 | Q13: =(C13+D13)/2*(F13-E13)*10000*K13/100000000 | R13: =(C13+D13)/2*(F13-E13)*G13*10000*K13/100000000 | S13: 0 | T13: =(C13+D13)/2*(I13-J13)*10000*K13/100000000 | U13: =SUM(P13:T13)-(O13-N13) | V13: 0.426
A14: SZ002385 | B14: 大北农 | C14: 395.87 | D14: 400 | E14: 10.8472 | F14: 18 | G14: -0.02 | H14: 0 | I14: 11.9 | J14: 11.9 | K14: 120 | L14: =E14*(1+G14)+H14-I14 | M14: =F14*(1+G14)+H14-J14 | N14: =C14*L14*10000*K14/100000000 | O14: =D14*M14*10000*K14/100000000 | P14: =(D14-C14)*(L14+M14)/2*10000*K14/100000000 | Q14: =(C14+D14)/2*(F14-E14)*10000*K14/100000000 | R14: =(C14+D14)/2*(F14-E14)*G14*10000*K14/100000000 | S14: 0 | T14: =(C14+D14)/2*(I14-J14)*10000*K14/100000000 | U14: =SUM(P14:T14)-(O14-N14) | V14: 1.34
A15: SH603363 | B15: 傲农生物 | C15: 136.36 | D15: 150 | E15: 10.8472 | F15: 18 | G15: 0 | H15: 0 | I15: 13 | J15: 12.6 | K15: 120 | L15: =E15*(1+G15)+H15-I15 | M15: =F15*(1+G15)+H15-J15 | N15: =C15*L15*10000*K15/100000000 | O15: =D15*M15*10000*K15/100000000 | P15: =(D15-C15)*(L15+M15)/2*10000*K15/100000000 | Q15: =(C15+D15)/2*(F15-E15)*10000*K15/100000000 | R15: =(C15+D15)/2*(F15-E15)*G15*10000*K15/100000000 | S15: 0 | T15: =(C15+D15)/2*(I15-J15)*10000*K15/100000000 | U15: =SUM(P15:T15)-(O15-N15) | V15: 0.403
A16: SZ002124 | B16: 天邦食品 | C16: 487.21 | D16: 450 | E16: 10.8472 | F16: 18 | G16: -0.036 | H16: 0 | I16: 12.65 | J16: 12.5 | K16: 120 | L16: =E16*(1+G16)+H16-I16 | M16: =F16*(1+G16)+H16-J16 | N16: =C16*L16*10000*K16/100000000 | O16: =D16*M16*10000*K16/100000000 | P16: =(D16-C16)*(L16+M16)/2*10000*K16/100000000 | Q16: =(C16+D16)/2*(F16-E16)*10000*K16/100000000 | R16: =(C16+D16)/2*(F16-E16)*G16*10000*K16/100000000 | S16: 0 | T16: =(C16+D16)/2*(I16-J16)*10000*K16/100000000 | U16: =SUM(P16:T16)-(O16-N16) | V16: 0.521
A17: SZ002548 | B17: 金新农 | C17: 80.16 | D17: 85 | E17: 10.8472 | F17: 18 | G17: 0.0191 | H17: 0 | I17: 12.77 | J17: 12.6 | K17: 120 | L17: =E17*(1+G17)+H17-I17 | M17: =F17*(1+G17)+H17-J17 | N17: =C17*L17*10000*K17/100000000 | O17: =D17*M17*10000*K17/100000000 | P17: =(D17-C17)*(L17+M17)/2*10000*K17/100000000 | Q17: =(C17+D17)/2*(F17-E17)*10000*K17/100000000 | R17: =(C17+D17)/2*(F17-E17)*G17*10000*K17/100000000 | S17: 0 | T17: =(C17+D17)/2*(I17-J17)*10000*K17/100000000 | U17: =SUM(P17:T17)-(O17-N17) | V17: 1.34

Sheet Screening
A1: 筛选快照（市值2026-10-08；资产负债2026-06-30；能繁/成本日期见列）
A3: code | B3: 公司 | C3: 池 | D3: 市值(亿) | E3: 有息负债(亿) | F3: 现金(亿) | G3: EV(亿) | H3: 资产负债率 | I3: 现金/短债 | J3: H1经营现金流(亿) | K3: H1资本开支(亿) | L3: H1归母净利(亿) | M3: 能繁(万头) | N3: 能繁日期 | O3: 2027育肥基准(万头) | P3: 市值/能繁(万元/头) | Q3: EV/能繁(万元/头) | R3: 市值/2027育肥(元/头) | S3: EV/2027育肥(元/头) | T3: 最新售价 | U3: 售价月份 | V3: 同月全国均价 | W3: 售价溢价 | X3: 最新成本 | Y3: 成本日期 | Z3: 成本口径 | AA3: 可转债余额(亿) | AB3: 转股价 | AC3: 风险标记
A4: SZ002714 | B4: 牧原股份 | C4: 核心 | D4: 2343.14 | E4: 748.02 | F4: 165.47 | G4: =D4+E4-F4 | H4: 0.5418 | I4: 0.291 | J4: -22.24 | K4: 65.21 | L4: -60.78 | M4: 311.3 | N4: 2026-06-30 | O4: =Company!E5 | P4: =IF(M4="","",D4*10000/M4/10000) | Q4: =IF(M4="","",G4*10000/M4/10000) | R4: =IF(O4="","",D4*100000000/(O4*10000)) | S4: =IF(O4="","",G4*100000000/(O4*10000)) | T4: 10.3 | U4: 2026-08 | V4: 10.814 | W4: =IF(OR(T4="",V4=""),"",T4/V4-1) | X4: 11.5 | Y4: 2026-07 | Z4: 生猪养殖完全成本（调研记录） | AC4: H股2026-02上市；能繁调减中
A5: SZ300498 | B5: 温氏股份 | C5: 核心 | D5: 989.44 | E5: 286.24 | F5: 36.75 | G5: =D5+E5-F5 | H5: 0.5894 | I5: 0.251 | J5: 4.22 | K5: 56.8 | L5: -43.66 | O5: =Company!E6 | P5: =IF(M5="","",D5*10000/M5/10000) | Q5: =IF(M5="","",G5*10000/M5/10000) | R5: =IF(O5="","",D5*100000000/(O5*10000)) | S5: =IF(O5="","",G5*100000000/(O5*10000)) | T5: 10.75 | U5: 2026-09 | V5: 10.89 | W5: =IF(OR(T5="",V5=""),"",T5/V5-1) | X5: 12 | Y5: 2026-08 | Z5: 肉猪养殖综合成本<6.0元/斤（上限，换算元/公斤） | AA5: 77.06 | AB5: 16.09 | AC5: 温氏转债2027-03-28到期；含黄羽鸡业务
A6: SZ000876 | B6: 新希望 | C6: 核心 | D6: 335.94 | E6: 579.09 | F6: 79.63 | G6: =D6+E6-F6 | H6: 0.707 | I6: 0.388 | J6: 16.46 | K6: 11.35 | L6: -17.02 | M6: 74 | N6: 2026年初 | O6: =Company!E7 | P6: =IF(M6="","",D6*10000/M6/10000) | Q6: =IF(M6="","",G6*10000/M6/10000) | R6: =IF(O6="","",D6*100000000/(O6*10000)) | S6: =IF(O6="","",G6*100000000/(O6*10000)) | T6: 10.46 | U6: 2026-08 | V6: 10.814 | W6: =IF(OR(T6="",V6=""),"",T6/V6-1) | X6: 12 | Y6: 2026-09 | Z6: 正常运营场线肥猪完全成本（不含闲置场线，闲置影响<1元/公斤） | AA6: 81.43 | AB6: 10.13 | AC6: 希望转2 2027-11-01到期；2026-08定增26亿（+4.59亿股）；饲料为主业
A7: SZ002100 | B7: 天康生物 | C7: 核心 | D7: 104.03 | E7: 65.33 | F7: 25.35 | G7: =D7+E7-F7 | H7: 0.5556 | I7: 0.831 | J7: 14.96 | K7: 1.52 | L7: -4.41 | M7: 19.4 | N7: 2026-07-31 | O7: =Company!E8 | P7: =IF(M7="","",D7*10000/M7/10000) | Q7: =IF(M7="","",G7*10000/M7/10000) | R7: =IF(O7="","",D7*100000000/(O7*10000)) | S7: =IF(O7="","",G7*100000000/(O7*10000)) | T7: 9.61 | U7: 2026-08 | V7: 10.814 | W7: =IF(OR(T7="",V7=""),"",T7/V7-1) | X7: 11.8 | Y7: 2026-06 | Z7: 生猪养殖成本（公司口径，是否含羌都未说明） | AC7: 羌都并购（并购贷款约半数）；业绩承诺2025-2027累计≥8.37亿
A8: SZ001201 | B8: 东瑞股份 | C8: 核心 | D8: 39.6 | E8: 24.27 | F8: 4.55 | G8: =D8+E8-F8 | H8: 0.5288 | I8: 0.29 | J8: -1.38 | K8: 0.89 | L8: -4.25 | M8: 9.2 | N8: 2026-06-30 | O8: =Company!E9 | P8: =IF(M8="","",D8*10000/M8/10000) | Q8: =IF(M8="","",G8*10000/M8/10000) | R8: =IF(O8="","",D8*100000000/(O8*10000)) | S8: =IF(O8="","",G8*100000000/(O8*10000)) | T8: 12.16 | U8: 2026-08 | V8: 10.814 | W8: =IF(OR(T8="",V8=""),"",T8/V8-1) | X8: 13.8 | Y8: 2026-07 | Z8: 完全成本（代养13.26） | AC8: 国家级生猪产能调控基地（自称）；广东能繁约为正常保有量109%（推断）
A9: SZ000048 | B9: 京基智农 | C9: 核心 | D9: 94.48 | E9: 19.75 | F9: 6.08 | G9: =D9+E9-F9 | H9: 0.6365 | I9: 0.457 | J9: 0.41 | K9: 0.95 | L9: -4.89 | M9: 10.29 | N9: 2025-12-31 | O9: =Company!E10 | P9: =IF(M9="","",D9*10000/M9/10000) | Q9: =IF(M9="","",G9*10000/M9/10000) | R9: =IF(O9="","",D9*100000000/(O9*10000)) | S9: =IF(O9="","",G9*100000000/(O9*10000)) | T9: 11.06 | U9: 2026-09 | V9: 10.89 | W9: =IF(OR(T9="",V9=""),"",T9/V9-1) | X9: 13.3 | Y9: 2026-03 | Z9: 生猪养殖完全成本（此后未披露） | AC9: 两大股东质押率接近100%
A10: SH605296 | B10: 神农集团 | C10: 核心 | D10: 158.58 | E10: 13.62 | F10: 4.5 | G10: =D10+E10-F10 | H10: 0.4075 | I10: 0.682 | J10: -3.75 | K10: 2.81 | L10: -8.09 | O10: =Company!E11 | P10: =IF(M10="","",D10*10000/M10/10000) | Q10: =IF(M10="","",G10*10000/M10/10000) | R10: =IF(O10="","",D10*100000000/(O10*10000)) | S10: =IF(O10="","",G10*100000000/(O10*10000)) | T10: 10.62 | U10: 2026-08 | V10: 10.814 | W10: =IF(OR(T10="",V10=""),"",T10/V10-1) | X10: 12 | Y10: 2026-07 | Z10: 完全成本 | AC10: 实控人离婚诉讼涉及股权分割风险
A11: SH603477 | B11: 巨星农牧 | C11: 核心 | D11: 71.91 | E11: 37.45 | F11: 6.94 | G11: =D11+E11-F11 | H11: 0.694 | I11: 0.345 | J11: -2.86 | K11: 1.6 | L11: -8.38 | O11: =Company!E12 | P11: =IF(M11="","",D11*10000/M11/10000) | Q11: =IF(M11="","",G11*10000/M11/10000) | R11: =IF(O11="","",D11*100000000/(O11*10000)) | S11: =IF(O11="","",G11*100000000/(O11*10000)) | T11: 11.05 | U11: 2026-09 | V11: 10.89 | W11: =IF(OR(T11="",V11=""),"",T11/V11-1) | X11: 12.4 | Y11: 2026-07 | Z11: 商品肥猪完全成本<6.2元/斤（上限，换算） | AA11: 9 | AB11: 24.84 | AC11: 巨星转债2028-04到期；控股股东质押61.58%
